Workbook

Sheet 2017 Website
C2: Jan | D2: Feb | E2: Mar | F2: Apr | G2: May | H2: Jun | I2: Jul | J2: Aug | K2: Sep | L2: Oct | M2: Nov | N2: Dec | O2: YTD (Average) | P2: TOTAL | R2: Obectifs 2017 | S2: % goals
A3: Traffic web | U3: moyenne par mois
A4: Visits | B4: Stats | C4: 44564 | D4: 39586 | E4: 45823 | F4: 39962 | G4: 47876 | H4: 41580 | I4: 37710 | J4: 42208 | K4: 43979 | L4: 45029 | M4: 44461 | N4: 39469 | O4: =AVERAGE(C4:N4) -> 42687.25 | P4: =SUM(C4:N4) -> 512247
B5: % M-1 | C5: =(C4-'2016 Website'!N4)/'2016 Website'!N4 -> -0.27749676 | D5: =(D4-C4)/C4 -> -0.11170451 | E5: =(E4-D4)/D4 -> 0.1575557 | F5: =(F4-E4)/E4 -> -0.1279052 | G5: =(G4-F4)/F4 -> 0.19803814 | H5: =(H4-G4)/G4 -> -0.13150639 | I5: =(I4-H4)/H4 -> -0.093073593 | J5: =(J4-I4)/I4 -> 0.11927871 | K5: =(K4-J4)/J4 -> 0.04195887 | ... N5: =(N4-M4)/M4 -> -0.11227818 | O5: =AVERAGE(C5:N5) -> -0.027156023
B6: % Y-1 | C6: =(C4-'2016 Website'!C4)/'2016 Website'!C4 -> 0.16619998 | D6: =(D4-'2016 Website'!D4)/'2016 Website'!D4 -> 0.11758561 | E6: =(E4-'2016 Website'!E4)/'2016 Website'!E4 -> 0.24191669 | F6: =(F4-'2016 Website'!F4)/'2016 Website'!F4 -> 0.092723743 | G6: =(G4-'2016 Website'!G4)/'2016 Website'!G4 -> 0.16178505 | H6: =(H4-'2016 Website'!H4)/'2016 Website'!H4 -> -0.51740387 | I6: =(I4-'2016 Website'!I4)/'2016 Website'!I4 -> -0.05443695 | J6: =(J4-'2016 Website'!J4)/'2016 Website'!J4 -> 0.14701886 | ... N6: =(N4-'2016 Website'!N4)/'2016 Website'!N4 -> -0.36010052 | O6: =AVERAGE(C6:N6) -> -0.0342091
A7: Users | B7: Total | C7: 32676 | D7: 29239 | E7: 33334 | F7: 29410 | G7: 35048 | H7: 30465 | I7: 24715 | J7: 32455 | K7: 33644 | L7: 33986 | M7: 33327 | N7: 29896 | O7: =AVERAGE(C7:N7) -> 31516.25 | P7: =SUM(C7:N7) -> 378195 | R7: 480000 | S7: =P7/R7 -> 0.78790625 | U7: =R7/12 -> 40000
B8: % M-1 | C8: =(C7-'2016 Website'!N6)/'2016 Website'!N6 -> -0.23500492 | D8: =(D7-C7)/C7 -> -0.10518423 | E8: =(E7-D7)/D7 -> 0.14005267 | F8: =(F7-E7)/E7 -> -0.11771765 | G8: =(G7-F7)/F7 -> 0.1917035 | H8: =(H7-G7)/G7 -> -0.13076352 | I8: =(I7-H7)/H7 -> -0.18874118 | J8: =(J7-I7)/I7 -> 0.31317014 | K8: =(K7-J7)/J7 -> 0.036635341 | ... N8: =(N7-M7)/M7 -> -0.10294956 | O8: =AVERAGE(C8:N8) -> -0.017335374
B9: % Y-1 | C9: =(C7-'2016 Website'!C6)/'2016 Website'!C6 -> 0.097541314 | D9: =(D7-'2016 Website'!D6)/'2016 Website'!D6 -> 0.069497787 | E9: =(E7-'2016 Website'!E6)/'2016 Website'!E6 -> 0.19024495 | F9: =(F7-'2016 Website'!F6)/'2016 Website'!F6 -> 0.039700216 | G9: =(G7-'2016 Website'!G6)/'2016 Website'!G6 -> 0.10047727 | H9: =(H7-'2016 Website'!H6)/'2016 Website'!H6 -> -0.55355442 | I9: =(I7-'2016 Website'!I6)/'2016 Website'!I6 -> -0.14457289 | J9: =(J7-'2016 Website'!J6)/'2016 Website'!J6 -> 0.18022474 | ... N9: =(N7-'2016 Website'!N6)/'2016 Website'!N6 -> -0.30008896 | O9: =AVERAGE(C9:N9) -> -0.054913867
A10: Bounce Rate | B10: Stats | C10: 0.4391 | D10: 0.4376 | E10: 0.4434 | F10: 0.4521 | G10: 0.5008 | H10: 0.4782 | I10: 0.4573 | J10: 0.4593 | K10: 0.4781 | L10: 0.4614 | M10: 0.4657 | N10: 0.4701 | O10: =AVERAGE(C10:N10) -> 0.461925 | R10: 48% max
B11: % M-1 | C11: =(C10-'2016 Website'!N8)/'2016 Website'!N8 -> -0.32446154 | D11: =(D10-C10)/C10 -> -0.0034160783 | E11: =(E10-D10)/D10 -> 0.013254113 | F11: =(F10-E10)/E10 -> 0.01962111 | G11: =(G10-F10)/F10 -> 0.10771953 | H11: =(H10-G10)/G10 -> -0.045127796 | I11: =(I10-H10)/H10 -> -0.043705563 | J11: =(J10-I10)/I10 -> 0.0043734966 | K11: =(K10-J10)/J10 -> 0.040931853 | ... N11: =(N10-M10)/M10 -> 0.0094481426 | O11: =AVERAGE(C11:N11) -> -0.0205811
B12: % Y-1 | C12: =(C10-'2016 Website'!C8)/'2016 Website'!C8 -> 0.021162791 | D12: =(D10-'2016 Website'!D8)/'2016 Website'!D8 -> -0.027555556 | E12: =(E10-'2016 Website'!E8)/'2016 Website'!E8 -> 0.0077272727 | F12: =(F10-'2016 Website'!F8)/'2016 Website'!F8 -> 0.0046666667 | G12: =(G10-'2016 Website'!G8)/'2016 Website'!G8 -> 0.065531915 | H12: =(H10-'2016 Website'!H8)/'2016 Website'!H8 -> -0.2528125 | I12: =(I10-'2016 Website'!I8)/'2016 Website'!I8 -> -0.0854 | J12: =(J10-'2016 Website'!J8)/'2016 Website'!J8 -> 0.020666667 | ... N12: =(N10-'2016 Website'!N8)/'2016 Website'!N8 -> -0.27676923 | O12: =AVERAGE(C12:N12) -> -0.080182825
A13: Pages/Session | B13: Stats | C13: 4.05 | D13: 3.95 | E13: 3.87 | F13: 3.82 | G13: 3.47 | H13: 3.64 | I13: 3.77 | J13: 3.71 | K13: 3.59 | L13: 3.66 | M13: 3.65 | N13: 3.69 | O13: =AVERAGE(C13:N13) -> 3.7391667 | R13: 3,6 mini
B14: % M-1 | C14: =('2017 Website'!C13-'2016 Website'!N10)/'2016 Website'!N10 -> 0.53992395 | D14: =(D13-C13)/C13 -> -0.024691358 | E14: =(E13-D13)/D13 -> -0.020253165 | F14: =(F13-E13)/E13 -> -0.012919897 | G14: =(G13-F13)/F13 -> -0.091623037 | H14: =(H13-G13)/G13 -> 0.048991354 | I14: =(I13-H13)/H13 -> 0.035714286 | J14: =(J13-I13)/I13 -> -0.015915119 | K14: =(K13-J13)/J13 -> -0.032345013 | ... N14: =(N13-M13)/M13 -> 0.010958904 | O14: =AVERAGE(C14:N14) -> 0.03788394
B15: % Y-1 | C15: =(C13-'2016 Website'!C10)/'2016 Website'!C10 -> 0.022727273 | D15: =(D13-'2016 Website'!D10)/'2016 Website'!D10 -> 0.018041237 | E15: =(E13-'2016 Website'!E10)/'2016 Website'!E10 -> -0.0025773196 | F15: =(F13-'2016 Website'!F10)/'2016 Website'!F10 -> 0.061111111 | G15: =(G13-'2016 Website'!G10)/'2016 Website'!G10 -> 0.032738095 | H15: =(H13-'2016 Website'!H10)/'2016 Website'!H10 -> 0.51037344 | I15: =(I13-'2016 Website'!I10)/'2016 Website'!I10 -> 0.12537313 | J15: =(J13-'2016 Website'!J10)/'2016 Website'!J10 -> 0.030555556 | ... N15: =(N13-'2016 Website'!N10)/'2016 Website'!N10 -> 0.40304183 | O15: =AVERAGE(C15:N15) -> 0.15168655
A16: Avg.Session Duration | B16: Stats | C16: 3.44 | D16: 3.35 | E16: 3.32 | F16: 3.24 | G16: 3.05 | H16: 3.12 | I16: 3.24 | J16: 3.19 | K16: 3.13 | L16: 3.23 | M16: 3.19 | N16: 3.17 | O16: =AVERAGE(C16:N16) -> 3.2225 | R16: 3 minutes mini
B17: % M-1 | C17: =(C16-'2016 Website'!N12)/'2016 Website'!N12 -> 0.58525346 | D17: =(D16-C16)/C16 -> -0.026162791 | E17: =(E16-D16)/D16 -> -0.0089552239 | F17: =(F16-E16)/E16 -> -0.024096386 | G17: =(G16-F16)/F16 -> -0.058641975 | H17: =(H16-G16)/G16 -> 0.02295082 | I17: =(I16-H16)/H16 -> 0.038461538 | J17: =(J16-I16)/I16 -> -0.015432099 | K17: =(K16-J16)/J16 -> -0.018808777 | ... N17: =(N16-M16)/M16 -> -0.0062695925 | O17: =AVERAGE(C17:N17) -> 0.042321996
B18: % Y-1 | C18: =(C16-'2016 Website'!C12)/'2016 Website'!C12 -> 0.088607595 | D18: =(D16-'2016 Website'!D12)/'2016 Website'!D12 -> 0.033950617 | E18: =(E16-'2016 Website'!E12)/'2016 Website'!E12 -> 0.01529052 | F18: =(F16-'2016 Website'!F12)/'2016 Website'!F12 -> 0.038461538 | G18: =(G16-'2016 Website'!G12)/'2016 Website'!G12 -> 0.0066006601 | H18: =(H16-'2016 Website'!H12)/'2016 Website'!H12 -> 1.0939597 | I18: =(I16-'2016 Website'!I12)/'2016 Website'!I12 -> 0.058823529 | J18: =(J16-'2016 Website'!J12)/'2016 Website'!J12 -> -0.0093167702 | ... N18: =(N16-'2016 Website'!N12)/'2016 Website'!N12 -> 0.46082949 | O18: =AVERAGE(C18:N18) -> 0.21468059
A19: Goals web
A20: Ecommerce Conversion Rate | B20: Stats | C20: 0.004 | D20: 0.0044 | E20: 0.0052 | F20: 0.0044 | G20: 0.0034 | H20: 0.0039 | O20: =AVERAGE(C20:N20) -> 0.0042166667
B21: % M-1 | C21: =(C20-'2016 Website'!N17)/'2016 Website'!N17 -> 0.81818182 | D21: =(D20-C20)/C20 -> 0.1 | E21: =(E20-D20)/D20 -> 0.18181818 | F21: =(F20-E20)/E20 -> -0.15384615 | G21: =(G20-F20)/F20 -> -0.22727273 | H21: =(H20-G20)/G20 -> 0.14705882 | O21: =AVERAGE(C21:N21) -> 0.14432332
A22: Revenue (€) | B22: Stats | C22: 212316.12 | D22: 302068.25 | E22: 199407.96 | F22: 274070 | G22: 311920.49 | H22: 169495 | O22: =AVERAGE(C22:N22) -> 244879.64 | P22: =SUM(C22:N22) -> 1469277.8
B23: % M-1 | C23: =(C22-'2016 Website'!N19)/'2016 Website'!N19 -> 0.84270196 | D23: =(D22-C22)/C22 -> 0.42272876 | E23: =(E22-D22)/D22 -> -0.33985793 | F23: =(F22-E22)/E22 -> 0.37441855 | G23: =(G22-F22)/F22 -> 0.13810519 | H23: =(H22-G22)/G22 -> -0.45660832 | I23: =(I22-H22)/H22 -> -1 | J23: =(J22-I22)/I22 -> #DIV/0! | K23: =(K22-J22)/J22 -> #DIV/0! | L23: =(L22-K22)/K22 -> #DIV/0! | O23: =AVERAGE(C23:N23) -> #DIV/0!
A24: Total Abandonment Rate | B24: Stats | C24: 0.4572 | D24: 0.4494 | E24: 0.4377 | F24: 0.4321 | G24: 0.4493 | H24: 0.4525 | I24: 0.4867 | J24: 0.4947 | K24: 0.4889 | L24: 0.4755 | O24: =AVERAGE(C24:N24) -> 0.4624
B25: % M-1 | C25: =(C24-'2016 Website'!N21)/'2016 Website'!N21 -> 0.0026315789 | D25: =(D24-C24)/C24 -> -0.017060367 | E25: =(E24-D24)/D24 -> -0.026034713 | F25: =(F24-E24)/E24 -> -0.012794151 | G25: =(G24-F24)/F24 -> 0.039805601 | H25: =(H24-G24)/G24 -> 0.0071221901 | I25: =(I24-H24)/H24 -> 0.07558011 | J25: =(J24-I24)/I24 -> 0.01643723 | K25: =(K24-J24)/J24 -> -0.011724277 | L25: =(L24-K24)/K24 -> -0.027408468 | O25: =AVERAGE(C25:N25) -> 0.0046554733
A26: Goal 1: Transaction Completed | B26: Stats | C26: 178 | D26: 171 | E26: 235 | F26: 174 | G26: 162 | H26: 162 | O26: =AVERAGE(C26:N26) -> 180.33333 | P26: =SUM(C26:N26) -> 1082 | R26: 1500 | S26: =P26/R26 -> 0.72133333 | U26: =R26/12 -> 125
B27: % M-1 | C27: =(C26-'2016 Website'!N23)/'2016 Website'!N23 -> 0.33834586 | D27: =(D26-C26)/C26 -> -0.039325843 | E27: =(E26-D26)/D26 -> 0.37426901 | F27: =(F26-E26)/E26 -> -0.25957447 | G27: =(G26-F26)/F26 -> -0.068965517 | H27: =(H26-G26)/G26 -> 0 | I27: =(I26-H26)/H26 -> -1 | J27: =(J26-I26)/I26 -> #DIV/0! | K27: =(K26-J26)/J26 -> #DIV/0! | O27: =AVERAGE(C27:N27) -> #DIV/0!
A28: Goal 2 : Brochure Request | B28: Stats | C28: 203 | D28: 198 | E28: 265 | F28: 190 | G28: 210 | H28: 218 | I28: 163 | J28: 152 | K28: 199 | L28: 197 | M28: 209 | N28: 157 | O28: =AVERAGE(C28:N28) -> 196.75 | P28: =SUM(C28:N28) -> 2361 | R28: 2200 | S28: =P28/R28 -> 1.0731818 | U28: =R28/12 -> 183.33333
B29: % M-1 | C29: =(C28-'2016 Website'!N25)/'2016 Website'!N25 -> 0.041025641 | D29: =(D28-C28)/C28 -> -0.024630542 | E29: =(E28-D28)/D28 -> 0.33838384 | F29: =(F28-E28)/E28 -> -0.28301887 | G29: =(G28-F28)/F28 -> 0.10526316 | H29: =(H28-G28)/G28 -> 0.038095238 | I29: =(I28-H28)/H28 -> -0.25229358 | J29: =(J28-I28)/I28 -> -0.067484663 | K29: =(K28-J28)/J28 -> 0.30921053 | ... N29: =(N28-M28)/M28 -> -0.24880383 | O29: =AVERAGE(C29:N29) -> 0.00055086483
A30: Goal 3 : Newsletter sign up | B30: Stats | C30: 109 | D30: 90 | E30: 108 | F30: 120 | G30: 102 | H30: 95 | I30: 91 | J30: 82 | K30: 122 | L30: 104 | M30: 87 | N30: 80 | O30: =AVERAGE(C30:N30) -> 99.166667 | P30: =SUM(C30:N30) -> 1190
B31: % M-1 | C31: =(C30-'2016 Website'!N27)/'2016 Website'!N27 -> 0.079207921 | D31: =(D30-C30)/C30 -> -0.17431193 | E31: =(E30-D30)/D30 -> 0.2 | F31: =(F30-E30)/E30 -> 0.11111111 | G31: =(G30-F30)/F30 -> -0.15 | H31: =(H30-G30)/G30 -> -0.068627451 | I31: =(I30-H30)/H30 -> -0.042105263 | J31: =(J30-I30)/I30 -> -0.098901099 | K31: =(K30-J30)/J30 -> 0.48780488 | ... N31: =(N30-M30)/M30 -> -0.08045977 | O31: =AVERAGE(C31:N31) -> -0.0039403435
A32: Goal 4 : Contact Request | B32: Stats | C32: 220 | D32: 176 | E32: 207 | F32: 174 | G32: 166 | H32: 137 | I32: 139 | J32: 180 | K32: 153 | L32: 194 | M32: 149 | N32: 126 | O32: =AVERAGE(C32:N32) -> 168.41667 | P32: =SUM(C32:N32) -> 2021 | R32: 1600 | S32: =P32/R32 -> 1.263125 | U32: =R32/12 -> 133.33333
B33: % M-1 | C33: =(C32-'2016 Website'!N29)/'2016 Website'!N29 -> 0.61764706 | D33: =(D32-C32)/C32 -> -0.2 | E33: =(E32-D32)/D32 -> 0.17613636 | F33: =(F32-E32)/E32 -> -0.15942029 | G33: =(G32-F32)/F32 -> -0.045977011 | H33: =(H32-G32)/G32 -> -0.1746988 | I33: =(I32-H32)/H32 -> 0.01459854 | J33: =(J32-I32)/I32 -> 0.29496403 | K33: =(K32-J32)/J32 -> -0.15 | ... N33: =(N32-M32)/M32 -> -0.15436242 | O33: =AVERAGE(C33:N33) -> 0.021241881
A34: Goal 5 : Book a tour | B34: Stats | C34: 38 | D34: 25 | E34: 33 | F34: 25 | G34: 26 | H34: 43 | I34: 36 | J34: 34 | K34: 37 | L34: 31 | M34: 28 | N34: 26 | O34: =AVERAGE(C34:N34) -> 31.833333 | P34: =SUM(C34:N34) -> 382
B35: % M-1 | C35: =(C34-'2016 Website'!N31)/'2016 Website'!N31 -> 0.52 | D35: =(D34-C34)/C34 -> -0.34210526 | E35: =(E34-D34)/D34 -> 0.32 | F35: =(F34-E34)/E34 -> -0.24242424 | G35: =(G34-F34)/F34 -> 0.04 | H35: =(H34-G34)/G34 -> 0.65384615 | I35: =(I34-H34)/H34 -> -0.1627907 | J35: =(J34-I34)/I34 -> -0.055555556 | K35: =(K34-J34)/J34 -> 0.088235294 | ... N35: =(N34-M34)/M34 -> -0.071428571 | O35: =AVERAGE(C35:N35) -> 0.04073673
A36: Goal 6 : New Account | B36: Stats | C36: 16 | D36: 16 | E36: 20 | F36: 24 | G36: 24 | H36: 16 | I36: 13 | J36: 15 | K36: 18 | L36: 22 | M36: 19 | N36: 13 | O36: =AVERAGE(C36:N36) -> 18 | P36: =SUM(C36:N36) -> 216
B37: % M-1 | C37: =(C36-'2016 Website'!N33)/'2016 Website'!N33 -> 1.2857143 | D37: =(D36-C36)/C36 -> 0 | E37: =(E36-D36)/D36 -> 0.25 | F37: =(F36-E36)/E36 -> 0.2 | G37: =(G36-F36)/F36 -> 0 | H37: =(H36-G36)/G36 -> -0.33333333 | I37: =(I36-H36)/H36 -> -0.1875 | J37: =(J36-I36)/I36 -> 0.15384615 | K37: =(K36-J36)/J36 -> 0.2 | ... N37: =(N36-M36)/M36 -> -0.31578947 | O37: =AVERAGE(C37:N37) -> 0.11156635
A38: Goal 7: Add to schoolbag | B38: Stats | C38: 1464 | D38: 1316 | E38: 1646 | F38: 1339 | G38: 1236 | H38: 1173 | I38: 1077 | J38: 1191 | K38: 1093 | L38: 1177 | M38: 1167 | N38: 1102 | O38: =AVERAGE(C38:N38) -> 1248.4167 | P38: =SUM(C38:N38) -> 14981
B39: % M-1 | C39: =(C38-'2016 Website'!N35)/'2016 Website'!N35 -> 0.41449275 | D39: =(D38-C38)/C38 -> -0.1010929 | E39: =(E38-D38)/D38 -> 0.25075988 | F39: =(F38-E38)/E38 -> -0.18651276 | G39: =(G38-F38)/F38 -> -0.076923077 | H39: =(H38-G38)/G38 -> -0.050970874 | I39: =(I38-H38)/H38 -> -0.081841432 | J39: =(J38-I38)/I38 -> 0.10584958 | K39: =(K38-J38)/J38 -> -0.082283795 | ... N39: =(N38-M38)/M38 -> -0.055698372 | O39: =AVERAGE(C39:N39) -> 0.017011294
A40: Newsletter subscribers | B40: Stats | C40: 41685 | D40: 42047 | E40: 42452 | F40: 42747 | G40: 43138 | H40: 43736 | I40: 44007 | J40: 44199 | K40: 44675 | L40: 45094 | M40: 45501 | N40: 45804 | O40: =AVERAGE(C40:N40) -> 43757.083 | P40: =N40 -> 45804 | R40: 44000 | S40: =P40/R40 -> 1.041 | U40: =R40/12 -> 3666.6667
B41: % M-2 | D41: =(D40-C40)/C40 -> 0.008684179 | E41: =(E40-D40)/D40 -> 0.0096320784 | F41: =(F40-E40)/E40 -> 0.0069490248 | G41: =(G40-F40)/F40 -> 0.0091468407 | H41: =(H40-G40)/G40 -> 0.013862488 | I41: =(I40-H40)/H40 -> 0.0061962685 | J41: =(J40-I40)/I40 -> 0.0043629423 | K41: =(K40-J40)/J40 -> 0.010769474 | ... N41: =(N40-M40)/M40 -> 0.0066591943 | O41: =AVERAGE(C41:N41) -> 0.0086060844
...

Sheet 2017 Website Graph

Sheet 2017 Newsletter
B1: Jan | C1: Feb | D1: Mar | E1: Apr | F1: May | G1: Jun | H1: Jul | I1: Aug | J1: Sep | K1: Oct | L1: Nov | M1: Dec | O1: Objectif 2017 | P1: % objectifs
A2: Subscribers | B2: 41934 | C2: 42047 | D2: 42453 | E2: 42749 | F2: 43138 | G2: 38971 | H2: 44007 | I2: 44199 | J2: 44663 | K2: 45094 | L2: 45501 | M2: 45804 | O2: 44000 | P2: =L2/O2 -> 1.0341136
A3: Opening rate | B3: =B4/B2 -> 0.15984643 | C3: =C4/C2 -> 0.12588294 | D3: =D4/D2 -> 0.1520505 | E3: =E4/E2 -> 0.16281083 | F3: =F4/F2 -> 0.12005656 | G3: =G4/G2 -> 0.14667317 | H3: =H4/H2 -> 0.146863 | I3: =I4/I2 -> 0.12043259 | ... M3: =M4/M2 -> 0.098855995 | N3: =AVERAGE(B3:G3) -> 0.1445534
A4: Opening | B4: 6703 | C4: 5293 | D4: 6455 | E4: 6960 | F4: 5179 | G4: 5716 | H4: 6463 | I4: 5323 | J4: 5686 | K4: 6339 | L4: 6024 | M4: 4528
A5: Click-trough | B5: 1751 | C5: 1882 | D5: 1534 | E5: 1330 | F5: 1983 | G5: 1061 | H5: 1804 | I5: 1252 | J5: 1426 | K5: 1779 | L5: 1446 | M5: 1208
A6: CTR | B6: =B5/B4 -> 0.26122632 | C6: =C5/C4 -> 0.35556395 | D6: =D5/D4 -> 0.23764524 | E6: =E5/E4 -> 0.19109195 | F6: =F5/F4 -> 0.38289245 | G6: =G5/G4 -> 0.18561931 | H6: =H5/H4 -> 0.27912734 | I6: =I5/I4 -> 0.23520571 | ... M6: =M5/M4 -> 0.26678445
A7: Brochures | B7: 1 | C7: 1 | D7: 1 | E7: 3 | F7: 3 | G7: 1 | H7: 1 | I7: 1 | J7: 5 | K7: 2 | L7: 2 | M7: 1
A8: Tour | B8: 1 | C8: 0 | D8: 0 | E8: 0 | F8: 7 | G8: 0 | H8: 1 | I8: 1 | J8: 7 | K8: 0 | L8: 0 | M8: 4
A9: Enrolment | B9: 9 | C9: 1 | D9: 2 | E9: 0 | F9: 2 | G9: 1 | H9: 1 | I9: 1 | J9: 2 | K9: 2 | L9: 1 | M9: 3
A10: unsubscribe | B10: 51 | C10: 25 | D10: 50 | E10: 40 | F10: 35 | G10: 39 | H10: 50 | I10: 48 | J10: 43 | K10: 57 | L10: 50 | M10: 29
A15: Newsletter conversions & subscriptions | K15: Newsletter conversions & subscriptions
A16: Months | B16: Subscribers | C16: Opening | D16: Opening rate | E16: Clicks | F16: Brochure | G16: Subscription / Enrolment | H16: Visit/event | I16: unsubscribe | K16: Months | L16: Subscribers | M16: Opening | N16: Opening rate | O16: Clicks | P16: Brochure | Q16: Subscription | R16: Visit/event
A17: 42370 | B17: CF statistiques 2016 | K17: 42370 | L17: =#REF! -> #REF! | M17: 12251 | N17: =M17/L17 -> #REF! | O17: =14313-M17 -> 2062 | P17: 27 | Q17: 1 | R17: 1
A18: 42401 | K18: 42401 | L18: =Q1 -> 0 | M18: 14473 | N18: =M18/L18 -> #DIV/0! | O18: 17202 | P18: 28 | Q18: 3 | R18: 1
A19: 42430 | K19: 42430 | L19: =Q2 -> 0 | M19: 12092 | N19: =M19/L19 -> #DIV/0! | O19: =13889-M19 -> 1797 | P19: 6 | Q19: 0 | R19: 4
A20: 42461 | K20: 42461 | L20: =Q3 -> 0 | M20: 13297 | N20: =M20/L20 -> #DIV/0! | O20: =14866-M20 -> 1569 | P20: 0 | Q20: 0 | R20: 0
A21: 42491 | K21: 42491 | L21: =Q4 -> 0 | M21: N/A | N21: =M21/L21 -> #VALUE! | O21: 1756 | P21: 2 | Q21: 3 | R21: 0
A22: 42522 | K22: 42522 | L22: =Q5 -> 0 | M22: =454+10833 -> 11287 | N22: =M22/L22 -> #DIV/0! | O22: =12892-M22 -> 1605 | P22: 2 | Q22: 2 | R22: 11
A23: 42552 | K23: 42552 | L23: =Q6 -> 0 | M23: N/A | N23: =M23/L23 -> #VALUE! | O23: 2035 | P23: 2 | Q23: 2 | R23: 0
A24: 42583 | K24: 42583 | L24: =Q7 -> 0 | M24: =8752+138 -> 8890 | N24: =M24/L24 -> #DIV/0!
A25: 42614 | B25: 41961 | C25: 4640 | D25: =C25/B25 -> 0.11057887 | E25: 1793 | F25: 1 | G25: 13 | H25: 1 | I25: 42 | J25: 38.64 | K25: 42614 | L25: =Q8 -> 0 | N25: =M25/L25 -> #DIV/0!
A26: 42644 | B26: 41399 | C26: 6861 | D26: =C26/B26 -> 0.16572864 | E26: 2693 | F26: 3 | G26: 3 | H26: 0 | I26: 53 | J26: 39.25 | K26: 42644 | L26: =Q9 -> 0 | N26: =M26/L26 -> #DIV/0!
A27: 42675 | B27: 41480 | C27: 6789 | D27: =C27/B27 -> 0.16366924 | E27: 1213 | F27: 1 | G27: 3 | H27: 0 | I27: 44 | J27: 17.86 | K27: 42675 | L27: =Q10 -> 0 | N27: =M27/L27 -> #DIV/0!
A28: 42705 | B28: 41685 | C28: 6509 | D28: =C28/B28 -> 0.1561473 | E28: 1699 | F28: 3 | G28: 1 | H28: 0 | I28: 55 | J28: 26.1 | K28: 42705 | L28: =Q11 -> 0 | N28: =M28/L28 -> #DIV/0!
A30: moyenne taux ouverture : 14,77
A31: moyenne taux clic : 29,57

Sheet 2017 Emailing
B1: 2017 01 Ateliers | C1: 2017 02 Ateliers | D1: 2017 03 Ateliers | E1: 2017 04 Ateliers | F1: 2017 05 Ateliers | G1: 2017 06 Ateliers | H1: 2017 07 Ateliers | I1: 2017 08 Ateliers | J1: 2017 09 Ateliers | K1: 2017 10 Ateliers | L1: 2017 11 Ateliers | M1: 2017 12 Ateliers
A2: Literature ID/Campaign id | B2: 1090 | C2: 1111 | D2: 1136 | E2: 1162 | F2: 1191 | G2: 1220 | H2: 1258 | I2: 2270 | J2: 2298 | K2: 2331
A3: Date | B3: 42741 | C3: 42773 | D3: 42801 | E3: 42829 | F3: 42857 | G3: 42895 | H3: 42929 | I3: 42948 | J3: 42983
A4: Subscribers | B4: 665 | C4: 5482 | D4: 2459 | E4: 1478 | F4: =216+192 -> 408 | G4: 1109 | H4: 673 | I4: 512 | J4: 359
A5: Opening rate | B5: =B6/B4 -> 0.39398496 | C5: =C6/C4 -> 0.19281284 | D5: =D6/D4 -> 0.28100854 | E5: =E6/E4 -> 0.27740189 | F5: 0.3083 | G5: 0.2673 | H5: 0.2793 | I5: 0.4316 | J5: 0.2451
A6: Opening | B6: 262 | C6: 1057 | D6: 691 | E6: 410 | F6: 127 | G6: 298 | H6: 188 | I6: 221 | J6: 90
A7: Click-trough | B7: 54 | C7: 121 | D7: 183 | E7: 46 | F7: 39 | G7: 49 | H7: 26 | I7: 8 | J7: 26
A8: CTR | B8: =B7/B6 -> 0.20610687 | C8: =C7/C6 -> 0.11447493 | D8: =D7/D6 -> 0.26483357 | E8: =E7/E6 -> 0.11219512 | F8: =F7/F6 -> 0.30708661 | G8: =G7/G6 -> 0.16442953 | H8: =H7/H6 -> 0.13829787 | I8: =I7/I6 -> 0.036199095 | J8: =J7/J6 -> 0.28888889
A9: Application | B9: 1 | C9: 0 | D9: 2 | E9: 1 | F9: 3 | G9: 0 | H9: 0 | I9: 0 | J9: 0
A10: Brochure | B10: 0 | C10: 0 | D10: 0 | E10: 0 | F10: 0 | G10: 0 | H10: 0 | I10: 0 | J10: 0
A11: Tour | B11: 0 | C11: 0 | D11: 0 | E11: 0 | F11: 0 | G11: 0 | H11: 0 | I11: 0 | J11: 0
A12: Contact | B12: 0 | C12: 0 | D12: 0 | E12: 0 | F12: 0 | G12: 0 | H12: 0 | I12: 0 | J12: 0
A14: Produits | B14: L’Atelier des Amoureux du 11 février | C14: Cours des modules à l’unité - champagne | D14: Boulangerie 2 J 06 et 07 avril | E14: Voyage Vignoble – Champagne 22 avril | F14: Visite des Vignobles du Val de Loire | G14: Visite des Vignobles de Champagne | H14: L’Art des Sauces et des Jus | I14: Initiation aux Vins et Spiritueux | J14: L’Art de la Cuisine Française - La Bretagne | K14: Module Vin - 1 cours du soir
B15: Cordon Vert, Cuisine Végétarienne du 28 janvier | C15: Cordon Vert du 11/02 | D15: Mon Premier Œuf de Pâques 8 avril | E15: Modules vins à l’unité à partir du 18 avril | F15: Mes Premiers Chocolats | G15: Mes Premiers Chocolats | H15: L'Atelier du Pain | I15: Cours intensif d’œnologie à Paris | J15: Les soirées dégustations : autour du vin | K15: L’Art de la Cuisine Française - La Bretagne
B16: La Boulangerie Traditionnelle 2 jours des 17 et 18 février | C16: L’École de la Pâtisserie du 10 mars | D16: Voyage Champagne 22 avril | E16: financiers du 12 mai | F16: Cordon Vert, Cuisine Végétarienne | G16: Accords Mets et Vins | H16: Les Secrets des Éclairs | I16: Les soirées dégustations : autour du vin | J16: Cordon Vert, Cuisine Végétarienne | K16: L'Atelier du Pain
B19: 2017 01 Prospects | C19: 2017 02 HEG Bourse | D19: 2017 04 SALES Relance Masterstudies | E19: 2017 02 SALES USA one-on-one meetings | F19: 2017 05 SALES Taiwan Yuanpei School Students visit LCBP | G19: 2017 09 SALES USA one-on-one meetings | H19: 2017 05 SALES Portugal | I19: 2017 09 SALES alumni du Brésil
A20: Literature ID/Campaign id | B20: 1095 | C20: 1117 | D20: 1168 | E20: 1134 | F20: 1193 | G20: 2306 | H20: 1195 | I20: 2319
A21: Date | B21: 42755 | C21: 42782 | D21: 42835 | E21: 42802 | F21: 42867 | G21: 42990 | H21: 42859
A22: Subscribers | B22: 7325 | C22: 8116 | D22: 1996 | E22: 719 | F22: 78 | G22: 5892 | H22: 511
A23: Opening rate | B23: =B24/B22 -> 0.19795222 | C23: =C24/C22 -> 0.21057171 | D23: =D24/D22 -> 0.17134269 | E23: 0.2507 | F23: 0.2289 | G23: 0.2512 | H23: 0.2224
A24: Opening | B24: 1450 | C24: 1709 | D24: 342 | E24: 181 | F24: 19 | G24: 1481 | H24: 116
A25: Click-trough | B25: =3273-2973 -> 300 | C25: 213 | D25: 85 | E25: 14 | F25: 0 | G25: 41 | H25: 9
A26: CTR | B26: =B25/B24 -> 0.20689655 | C26: =C25/C24 -> 0.12463429 | D26: =D25/D24 -> 0.24853801 | E26: =E25/E24 -> 0.077348066 | F26: =F25/F24 -> 0 | G26: =G25/G24 -> 0.027683997 | H26: =H25/H24 -> 0.077586207
A27: Application | B27: 0
A28: Brochure | B28: 0
A29: Tour | B29: 1
A30: Contact | B30: 0

Sheet 2016 Website
C2: Jan | D2: Feb | E2: Mar | F2: Apr | G2: May | H2: Jun | I2: Jul | J2: Aug | K2: Sep | L2: Oct | M2: Nov | N2: Dec | O2: YTD (Average) | P2: TOTAL | Q2: % Y-1
A3: Traffic
A4: Visits | B4: Stats | C4: 38213 | D4: 35421 | E4: 36897 | F4: 36571 | G4: 41209 | H4: 86159 | I4: 39881 | J4: 36798 | K4: 40124 | L4: 56808 | M4: 63023 | N4: 61680 | O4: =AVERAGE(C4:N4) -> 47732 | P4: =SUM(C4:N4) -> 572784
B5: % M-1 | D5: =(D4-C4)/C4 -> -0.07306414 | E5: =(E4-D4)/D4 -> 0.041670196 | F5: =(F4-E4)/E4 -> -0.0088354067 | G5: =(G4-F4)/F4 -> 0.1268218 | H5: =(H4-G4)/G4 -> 1.0907811 | I5: =(I4-H4)/H4 -> -0.53712323 | J5: =(J4-I4)/I4 -> -0.077304982 | K5: =(K4-J4)/J4 -> 0.090385347 | ... N5: =(N4-M4)/M4 -> -0.021309681 | O5: =AVERAGE(C5:N5) -> 0.10520324
A6: Users | B6: Total | C6: 29772 | D6: 27339 | E6: 28006 | F6: 28287 | G6: 31848 | H6: 68239 | I6: 28892 | J6: 27499 | K6: 29565 | L6: 43385 | M6: 45022 | N6: 42714 | O6: =AVERAGE(C6:N6) -> 35880.667 | P6: =SUM(C6:N6) -> 430568
B7: Total % | D7: =(D6-C6)/C6 -> -0.08172108 | E7: =(E6-D6)/D6 -> 0.024397381 | F7: =(F6-E6)/E6 -> 0.010033564 | G7: =(G6-F6)/F6 -> 0.12588822 | H7: =(H6-G6)/G6 -> 1.1426463 | I7: =(I6-H6)/H6 -> -0.57660575 | J7: =(J6-I6)/I6 -> -0.048214038 | K7: =(K6-J6)/J6 -> 0.075130005 | ... N7: =(N6-M6)/M6 -> -0.051263827 | O7: =AVERAGE(C7:N7) -> 0.10231521
A8: Bounce Rate | B8: Stats | C8: 0.43 | D8: 0.45 | E8: 0.44 | F8: 0.45 | G8: 0.47 | H8: 0.64 | I8: 0.5 | J8: 0.45 | K8: 0.46 | L8: 0.59 | M8: 0.63 | N8: 0.65 | O8: =AVERAGE(C8:N8) -> 0.51333333
B9: % M-1 | D9: =(D8-C8)/C8 -> 0.046511628 | E9: =(E8-D8)/D8 -> -0.022222222 | F9: =(F8-E8)/E8 -> 0.022727273 | G9: =(G8-F8)/F8 -> 0.044444444 | H9: =(H8-G8)/G8 -> 0.36170213 | I9: =(I8-H8)/H8 -> -0.21875 | J9: =(J8-I8)/I8 -> -0.1 | K9: =(K8-J8)/J8 -> 0.022222222 | ... N9: =(N8-M8)/M8 -> 0.031746032 | O9: =AVERAGE(C9:N9) -> 0.048980619
A10: Pages/Session | B10: Stats | C10: 3.96 | D10: 3.88 | E10: 3.88 | F10: 3.6 | G10: 3.36 | H10: 2.41 | I10: 3.35 | J10: 3.6 | K10: 3.6 | L10: 2.86 | M10: 2.72 | N10: 2.63 | O10: =AVERAGE(C10:N10) -> 3.3208333
B11: % M-1 | D11: =(D10-C10)/C10 -> -0.02020202 | E11: =(E10-D10)/D10 -> 0 | F11: =(F10-E10)/E10 -> -0.072164948 | G11: =(G10-F10)/F10 -> -0.066666667 | H11: =(H10-G10)/G10 -> -0.2827381 | I11: =(I10-H10)/H10 -> 0.39004149 | J11: =(J10-I10)/I10 -> 0.074626866 | K11: =(K10-J10)/J10 -> 0 | ... N11: =(N10-M10)/M10 -> -0.033088235 | O11: =AVERAGE(C11:N11) -> -0.024063474
A12: Avg.Session Duration | B12: Stats | C12: 3.16 | D12: 3.24 | E12: 3.27 | F12: 3.12 | G12: 3.03 | H12: 1.49 | I12: 3.06 | J12: 3.22 | K12: 3.2 | L12: 2.34 | M12: 2.23 | N12: 2.17 | O12: =AVERAGE(C12:N12) -> 2.7941667
B13: % M-1 | D13: =(D12-C12)/C12 -> 0.025316456 | E13: =(E12-D12)/D12 -> 0.0092592593 | F13: =(F12-E12)/E12 -> -0.04587156 | G13: =(G12-F12)/F12 -> -0.028846154 | H13: =(H12-G12)/G12 -> -0.50825083 | I13: =(I12-H12)/H12 -> 1.0536913 | J13: =(J12-I12)/I12 -> 0.052287582 | K13: =(K12-J12)/J12 -> -0.0062111801 | ... N13: =(N12-M12)/M12 -> -0.02690583 | O13: =AVERAGE(C13:N13) -> 0.01897368
A14: Goals
A15: Transaction | B15: Stats | C15: 0 | D15: 20 | E15: 60 | F15: 84 | G15: 70 | H15: 139 | I15: 125 | J15: 137 | K15: 172 | L15: 132 | M15: 192 | N15: 138 | O15: =AVERAGE(C15:N15) -> 105.75 | P15: =SUM(C15:N15) -> 1269
B16: % M-1 | E16: =(E15-D15)/D15 -> 2 | F16: =(F15-E15)/E15 -> 0.4 | G16: =(G15-F15)/F15 -> -0.16666667 | H16: =(H15-G15)/G15 -> 0.98571429 | I16: =(I15-H15)/H15 -> -0.10071942 | J16: =(J15-I15)/I15 -> 0.096 | K16: =(K15-J15)/J15 -> 0.25547445 | L16: =(L15-K15)/K15 -> -0.23255814 | ... N16: =(N15-M15)/M15 -> -0.28125 | O16: =AVERAGE(C16:N16) -> 0.341054
A17: Ecommerce Conversion Rate | B17: Stats | C17: 0 | D17: 0.0006 | E17: 0.0016 | F17: 0.0023 | G17: 0.0017 | H17: 0.0016 | I17: 0.0031 | J17: 0.0037 | K17: 0.0043 | L17: 0.0023 | M17: 0.0031 | N17: 0.0022 | O17: =AVERAGE(C17:N17) -> 0.0022083333
B18: % M-1 | E18: =(E17-D17)/D17 -> 1.6666667 | F18: =(F17-E17)/E17 -> 0.4375 | G18: =(G17-F17)/F17 -> -0.26086957 | H18: =(H17-G17)/G17 -> -0.058823529 | I18: =(I17-H17)/H17 -> 0.9375 | J18: =(J17-I17)/I17 -> 0.19354839 | K18: =(K17-J17)/J17 -> 0.16216216 | L18: =(L17-K17)/K17 -> -0.46511628 | ... N18: =(N17-M17)/M17 -> -0.29032258 | O18: =AVERAGE(C18:N18) -> 0.26700713
A19: Revenue (€) | B19: Stats | E19: 118739 | F19: 185825 | G19: 223524 | H19: 214230 | I19: 106188 | J19: 135355 | K19: 96785 | L19: 94095 | M19: 282098 | N19: 115220 | O19: =AVERAGE(C19:N19) -> 157205.9 | P19: =SUM(C19:N19) -> 1572059
B20: % M-1 | F20: =(F19-E19)/E19 -> 0.56498707 | G20: =(G19-F19)/F19 -> 0.20287367 | H20: =(H19-G19)/G19 -> -0.041579428 | I20: =(I19-H19)/H19 -> -0.50432713 | J20: =(J19-I19)/I19 -> 0.27467322 | K20: =(K19-J19)/J19 -> -0.28495438 | L20: =(L19-K19)/K19 -> -0.027793563 | M20: =(M19-L19)/L19 -> 1.9980126 | N20: =(N19-M19)/M19 -> -0.59156038 | O20: =AVERAGE(C20:N20) -> 0.17670353
A21: Total Abandonment Rate | B21: Stats | C21: 0.769 | D21: 0.623 | E21: 0.42 | F21: 0.48 | G21: 0.491 | H21: 0.461 | I21: 0.457 | J21: 0.45 | K21: 0.437 | L21: 0.464 | M21: 0.459 | N21: 0.456 | O21: =AVERAGE(C21:N21) -> 0.49725
B22: % M-1 | D22: =(D21-C21)/C21 -> -0.18985696 | E22: =(E21-D21)/D21 -> -0.3258427 | F22: =(F21-E21)/E21 -> 0.14285714 | G22: =(G21-F21)/F21 -> 0.022916667 | H22: =(H21-G21)/G21 -> -0.061099796 | I22: =(I21-H21)/H21 -> -0.0086767896 | J22: =(J21-I21)/I21 -> -0.015317287 | K22: =(K21-J21)/J21 -> -0.028888889 | ... N22: =(N21-M21)/M21 -> -0.0065359477 | O22: =AVERAGE(C22:N22) -> -0.038130502
A23: Goal 1: Transcation Completed | B23: Stats | C23: 227 | D23: 224 | E23: 58 | F23: 84 | G23: 70 | H23: 135 | I23: 125 | J23: 134 | K23: 171 | L23: 129 | M23: 171 | N23: 133 | O23: =AVERAGE(C23:N23) -> 138.41667 | P23: =SUM(C23:N23) -> 1661
B24: % M-1 | D24: =(D23-C23)/C23 -> -0.013215859 | E24: =(E23-D23)/D23 -> -0.74107143 | F24: =(F23-E23)/E23 -> 0.44827586 | G24: =(G23-F23)/F23 -> -0.16666667 | H24: =(H23-G23)/G23 -> 0.92857143 | I24: =(I23-H23)/H23 -> -0.074074074 | J24: =(J23-I23)/I23 -> 0.072 | K24: =(K23-J23)/J23 -> 0.2761194 | ... N24: =(N23-M23)/M23 -> -0.22222222 | O24: =AVERAGE(C24:N24) -> 0.0534258
A25: Goal 2 : Brochure Request | B25: Stats | C25: 108 | D25: 165 | E25: 225 | F25: 214 | G25: 240 | H25: 244 | I25: 202 | J25: 222 | K25: 230 | L25: 212 | M25: 222 | N25: 195 | O25: =AVERAGE(C25:N25) -> 206.58333 | P25: =SUM(C25:N25) -> 2479
B26: % M-1 | D26: =(D25-C25)/C25 -> 0.52777778 | E26: =(E25-D25)/D25 -> 0.36363636 | F26: =(F25-E25)/E25 -> -0.048888889 | G26: =(G25-F25)/F25 -> 0.12149533 | H26: =(H25-G25)/G25 -> 0.016666667 | I26: =(I25-H25)/H25 -> -0.17213115 | J26: =(J25-I25)/I25 -> 0.099009901 | K26: =(K25-J25)/J25 -> 0.036036036 | ... N26: =(N25-M25)/M25 -> -0.12162162 | O26: =AVERAGE(C26:N26) -> 0.071899032
A27: Goal 3 : Newsletter sign up | B27: Stats | C27: 35 | D27: 74 | E27: 103 | F27: 106 | G27: 84 | H27: 121 | I27: 90 | J27: 107 | K27: 118 | L27: 73 | M27: 95 | N27: 101 | O27: =AVERAGE(C27:N27) -> 92.25 | P27: =SUM(C27:N27) -> 1107
B28: % M-1 | D28: =(D27-C27)/C27 -> 1.1142857 | E28: =(E27-D27)/D27 -> 0.39189189 | F28: =(F27-E27)/E27 -> 0.029126214 | G28: =(G27-F27)/F27 -> -0.20754717 | H28: =(H27-G27)/G27 -> 0.44047619 | I28: =(I27-H27)/H27 -> -0.25619835 | J28: =(J27-I27)/I27 -> 0.18888889 | K28: =(K27-J27)/J27 -> 0.10280374 | ... N28: =(N27-M27)/M27 -> 0.063157895 | O28: =AVERAGE(C28:N28) -> 0.16244536
A29: Goal 4 : Contact Request | B29: Stats | C29: 0 | D29: 65 | E29: 192 | F29: 157 | G29: 164 | H29: 175 | I29: 165 | J29: 154 | K29: 156 | L29: 163 | M29: 158 | N29: 136 | O29: =AVERAGE(C29:N29) -> 140.41667 | P29: =SUM(C29:N29) -> 1685
B30: % M-1 | E30: =(E29-D29)/D29 -> 1.9538462 | F30: =(F29-E29)/E29 -> -0.18229167 | G30: =(G29-F29)/F29 -> 0.044585987 | H30: =(H29-G29)/G29 -> 0.067073171 | I30: =(I29-H29)/H29 -> -0.057142857 | J30: =(J29-I29)/I29 -> -0.066666667 | K30: =(K29-J29)/J29 -> 0.012987013 | L30: =(L29-K29)/K29 -> 0.044871795 | ... N30: =(N29-M29)/M29 -> -0.13924051 | O30: =AVERAGE(C30:N30) -> 0.16473476
A31: Goal 5 : Book a tour | B31: Stats | C31: 0 | D31: 12 | E31: 24 | F31: 31 | G31: 25 | H31: 21 | I31: 27 | J31: 27 | K31: 37 | L31: 29 | M31: 20 | N31: 25 | O31: =AVERAGE(C31:N31) -> 23.166667 | P31: =SUM(C31:N31) -> 278
B32: % M-1 | E32: =(E31-D31)/D31 -> 1 | F32: =(F31-E31)/E31 -> 0.29166667 | G32: =(G31-F31)/F31 -> -0.19354839 | H32: =(H31-G31)/G31 -> -0.16 | I32: =(I31-H31)/H31 -> 0.28571429 | J32: =(J31-I31)/I31 -> 0 | K32: =(K31-J31)/J31 -> 0.37037037 | L32: =(L31-K31)/K31 -> -0.21621622 | ... N32: =(N31-M31)/M31 -> 0.25 | O32: =AVERAGE(C32:N32) -> 0.13176419
A33: Goal 6 : New Account | B33: Stats | C33: 0 | D33: 11 | E33: 18 | F33: 14 | G33: 12 | H33: 13 | I33: 7 | J33: 14 | K33: 17 | L33: 13 | M33: 9 | N33: 7 | O33: =AVERAGE(C33:N33) -> 11.25 | P33: =SUM(C33:N33) -> 135
B34: % M-1 | E34: =(E33-D33)/D33 -> 0.63636364 | F34: =(F33-E33)/E33 -> -0.22222222 | G34: =(G33-F33)/F33 -> -0.14285714 | H34: =(H33-G33)/G33 -> 0.083333333 | I34: =(I33-H33)/H33 -> -0.46153846 | J34: =(J33-I33)/I33 -> 1 | K34: =(K33-J33)/J33 -> 0.21428571 | L34: =(L33-K33)/K33 -> -0.23529412 | ... N34: =(N33-M33)/M33 -> -0.22222222 | O34: =AVERAGE(C34:N34) -> 0.034215621
A35: Goal 7: Add to schoolbag | B35: Stats | C35: 0 | D35: 375 | E35: 1080 | F35: 912 | G35: 944 | H35: 1111 | I35: 948 | J35: 1020 | K35: 1161 | L35: 1026 | M35: 1222 | N35: 1035 | O35: =AVERAGE(C35:N35) -> 902.83333 | P35: =SUM(C35:N35) -> 10834
B36: % M-1 | E36: =(E35-D35)/D35 -> 1.88 | F36: =(F35-E35)/E35 -> -0.15555556 | G36: =(G35-F35)/F35 -> 0.035087719 | H36: =(H35-G35)/G35 -> 0.17690678 | I36: =(I35-H35)/H35 -> -0.14671467 | J36: =(J35-I35)/I35 -> 0.075949367 | K36: =(K35-J35)/J35 -> 0.13823529 | L36: =(L35-K35)/K35 -> -0.11627907 | ... N36: =(N35-M35)/M35 -> -0.15302782 | O36: =AVERAGE(C36:N36) -> 0.19256352
