Workbook

Sheet Graph1_CA_bilan
B1: COL_1
A2: CA_AJOUTE_2022 | B2: =IFERROR(__xludf.DUMMYFUNCTION("IMPORTRANGE(""https://docs.google.com/spreadsheets/d/1zA5LDh046PMNVU8ONXHA9gKBkE8m_N5laGAT0t2JyUg/edit?usp=sharing"",""Perf_globales!G3"")"),71666.66666666667) -> 71666.667
A3: CA_REEL_2023 | B3: =IFERROR(__xludf.DUMMYFUNCTION("IMPORTRANGE(""https://docs.google.com/spreadsheets/d/1zA5LDh046PMNVU8ONXHA9gKBkE8m_N5laGAT0t2JyUg/edit?usp=sharing"",""Perf_globales!J3"")"),290133.3299999999) -> 290133.33
A4: CA_AUTRES_SERVICES | B4: =IFERROR(__xludf.DUMMYFUNCTION("IMPORTRANGE(""https://docs.google.com/spreadsheets/d/1zA5LDh046PMNVU8ONXHA9gKBkE8m_N5laGAT0t2JyUg/edit?usp=sharing"",""Perf_globales!D13"")"),10202.82) -> 10202.82

Sheet Graph2_CA_travaille
A1: CRITERES | B1: COL_1
A2: CA_REEL_2023 | B2: =IFERROR(__xludf.DUMMYFUNCTION("IMPORTRANGE(""https://docs.google.com/spreadsheets/d/1zA5LDh046PMNVU8ONXHA9gKBkE8m_N5laGAT0t2JyUg/edit?usp=sharing"",""Perf_globales!J3"")"),290133.3299999999) -> 290133.33
A3: CA_AUTRES_SERVICES | B3: =IFERROR(__xludf.DUMMYFUNCTION("IMPORTRANGE(""https://docs.google.com/spreadsheets/d/1zA5LDh046PMNVU8ONXHA9gKBkE8m_N5laGAT0t2JyUg/edit?usp=sharing"",""Perf_globales!D13"")"),10202.82) -> 10202.82
A4: CA_REPORTE_2024 | B4: =IFERROR(__xludf.DUMMYFUNCTION("IMPORTRANGE(""https://docs.google.com/spreadsheets/d/1zA5LDh046PMNVU8ONXHA9gKBkE8m_N5laGAT0t2JyUg/edit?usp=sharing"",""Perf_globales!M3"")"),41458.333333333336) -> 41458.333

Sheet Graph3_perf_mois
A1: MOIS_2023 | B1: CA_HT_2023 | C1: CA_HT_2022 | D1: VENTES_2023 | E1: VENTES_2022
A2: JANVIER | B2: =IFERROR(__xludf.DUMMYFUNCTION("IMPORTRANGE(""https://docs.google.com/spreadsheets/d/1zA5LDh046PMNVU8ONXHA9gKBkE8m_N5laGAT0t2JyUg/edit?usp=sharing"",""Perf_mois!C2"")"),16666.666666666668) -> 16666.667 | C2: 0 | D2: =IFERROR(__xludf.DUMMYFUNCTION("IMPORTRANGE(""https://docs.google.com/spreadsheets/d/1zA5LDh046PMNVU8ONXHA9gKBkE8m_N5laGAT0t2JyUg/edit?usp=sharing"",""Perf_mois!B2"")"),2.0) -> 2 | E2: 0
A3: FEVRIER | B3: =IFERROR(__xludf.DUMMYFUNCTION("IMPORTRANGE(""https://docs.google.com/spreadsheets/d/1zA5LDh046PMNVU8ONXHA9gKBkE8m_N5laGAT0t2JyUg/edit?usp=sharing"",""Perf_mois!C3"")"),29166.666666666668) -> 29166.667 | C3: 0 | D3: =IFERROR(__xludf.DUMMYFUNCTION("IMPORTRANGE(""https://docs.google.com/spreadsheets/d/1zA5LDh046PMNVU8ONXHA9gKBkE8m_N5laGAT0t2JyUg/edit?usp=sharing"",""Perf_mois!B3"")"),4.0) -> 4 | E3: 0
A4: MARS | B4: =IFERROR(__xludf.DUMMYFUNCTION("IMPORTRANGE(""https://docs.google.com/spreadsheets/d/1zA5LDh046PMNVU8ONXHA9gKBkE8m_N5laGAT0t2JyUg/edit?usp=sharing"",""Perf_mois!C4"")"),28749.99666666667) -> 28749.997 | C4: 19375 | D4: =IFERROR(__xludf.DUMMYFUNCTION("IMPORTRANGE(""https://docs.google.com/spreadsheets/d/1zA5LDh046PMNVU8ONXHA9gKBkE8m_N5laGAT0t2JyUg/edit?usp=sharing"",""Perf_mois!B4"")"),6.0) -> 6 | E4: 3
A5: AVRIL | B5: =IFERROR(__xludf.DUMMYFUNCTION("IMPORTRANGE(""https://docs.google.com/spreadsheets/d/1zA5LDh046PMNVU8ONXHA9gKBkE8m_N5laGAT0t2JyUg/edit?usp=sharing"",""Perf_mois!C5"")"),22383.333333333336) -> 22383.333 | C5: 0 | D5: =IFERROR(__xludf.DUMMYFUNCTION("IMPORTRANGE(""https://docs.google.com/spreadsheets/d/1zA5LDh046PMNVU8ONXHA9gKBkE8m_N5laGAT0t2JyUg/edit?usp=sharing"",""Perf_mois!B5"")"),3.0) -> 3 | E5: 0
A6: MAI | B6: =IFERROR(__xludf.DUMMYFUNCTION("IMPORTRANGE(""https://docs.google.com/spreadsheets/d/1zA5LDh046PMNVU8ONXHA9gKBkE8m_N5laGAT0t2JyUg/edit?usp=sharing"",""Perf_mois!C6"")"),12500.0) -> 12500 | C6: 15833.33 | D6: =IFERROR(__xludf.DUMMYFUNCTION("IMPORTRANGE(""https://docs.google.com/spreadsheets/d/1zA5LDh046PMNVU8ONXHA9gKBkE8m_N5laGAT0t2JyUg/edit?usp=sharing"",""Perf_mois!B6"")"),2.0) -> 2 | E6: 2
A7: JUIN | B7: =IFERROR(__xludf.DUMMYFUNCTION("IMPORTRANGE(""https://docs.google.com/spreadsheets/d/1zA5LDh046PMNVU8ONXHA9gKBkE8m_N5laGAT0t2JyUg/edit?usp=sharing"",""Perf_mois!C7"")"),37500.00000000001) -> 37500 | C7: 15000 | D7: =IFERROR(__xludf.DUMMYFUNCTION("IMPORTRANGE(""https://docs.google.com/spreadsheets/d/1zA5LDh046PMNVU8ONXHA9gKBkE8m_N5laGAT0t2JyUg/edit?usp=sharing"",""Perf_mois!B7"")"),5.0) -> 5 | E7: 2
A8: JUILLET | B8: =IFERROR(__xludf.DUMMYFUNCTION("IMPORTRANGE(""https://docs.google.com/spreadsheets/d/1zA5LDh046PMNVU8ONXHA9gKBkE8m_N5laGAT0t2JyUg/edit?usp=sharing"",""Perf_mois!C8"")"),84000.0) -> 84000 | C8: 30833.33 | D8: =IFERROR(__xludf.DUMMYFUNCTION("IMPORTRANGE(""https://docs.google.com/spreadsheets/d/1zA5LDh046PMNVU8ONXHA9gKBkE8m_N5laGAT0t2JyUg/edit?usp=sharing"",""Perf_mois!B8"")"),7.0) -> 7 | E8: 4
A9: AOUT | B9: =IFERROR(__xludf.DUMMYFUNCTION("IMPORTRANGE(""https://docs.google.com/spreadsheets/d/1zA5LDh046PMNVU8ONXHA9gKBkE8m_N5laGAT0t2JyUg/edit?usp=sharing"",""Perf_mois!C9"")"),33333.333333333336) -> 33333.333 | C9: 29854.17 | D9: =IFERROR(__xludf.DUMMYFUNCTION("IMPORTRANGE(""https://docs.google.com/spreadsheets/d/1zA5LDh046PMNVU8ONXHA9gKBkE8m_N5laGAT0t2JyUg/edit?usp=sharing"",""Perf_mois!B9"")"),4.0) -> 4 | E9: 3
A10: SEPTEMBRE | B10: =IFERROR(__xludf.DUMMYFUNCTION("IMPORTRANGE(""https://docs.google.com/spreadsheets/d/1zA5LDh046PMNVU8ONXHA9gKBkE8m_N5laGAT0t2JyUg/edit?usp=sharing"",""Perf_mois!C10"")"),16666.666666666668) -> 16666.667 | C10: 42083.33 | D10: =IFERROR(__xludf.DUMMYFUNCTION("IMPORTRANGE(""https://docs.google.com/spreadsheets/d/1zA5LDh046PMNVU8ONXHA9gKBkE8m_N5laGAT0t2JyUg/edit?usp=sharing"",""Perf_mois!B10"")"),2.0) -> 2 | E10: 7
A11: OCTOBRE | B11: =IFERROR(__xludf.DUMMYFUNCTION("IMPORTRANGE(""https://docs.google.com/spreadsheets/d/1zA5LDh046PMNVU8ONXHA9gKBkE8m_N5laGAT0t2JyUg/edit?usp=sharing"",""Perf_mois!C11"")"),35833.33333333334) -> 35833.333 | C11: 28666.67 | D11: =IFERROR(__xludf.DUMMYFUNCTION("IMPORTRANGE(""https://docs.google.com/spreadsheets/d/1zA5LDh046PMNVU8ONXHA9gKBkE8m_N5laGAT0t2JyUg/edit?usp=sharing"",""Perf_mois!B11"")"),5.0) -> 5 | E11: 4
A12: NOVEMBRE | B12: =IFERROR(__xludf.DUMMYFUNCTION("IMPORTRANGE(""https://docs.google.com/spreadsheets/d/1zA5LDh046PMNVU8ONXHA9gKBkE8m_N5laGAT0t2JyUg/edit?usp=sharing"",""Perf_mois!C12"")"),15000.0) -> 15000 | C12: 21666.67 | D12: =IFERROR(__xludf.DUMMYFUNCTION("IMPORTRANGE(""https://docs.google.com/spreadsheets/d/1zA5LDh046PMNVU8ONXHA9gKBkE8m_N5laGAT0t2JyUg/edit?usp=sharing"",""Perf_mois!B12"")"),2.0) -> 2 | E12: 3
A13: DECEMBRE | B13: =IFERROR(__xludf.DUMMYFUNCTION("IMPORTRANGE(""https://docs.google.com/spreadsheets/d/1zA5LDh046PMNVU8ONXHA9gKBkE8m_N5laGAT0t2JyUg/edit?usp=sharing"",""Perf_mois!C13"")"),30000.000000000004) -> 30000 | C13: 66666.67 | D13: =IFERROR(__xludf.DUMMYFUNCTION("IMPORTRANGE(""https://docs.google.com/spreadsheets/d/1zA5LDh046PMNVU8ONXHA9gKBkE8m_N5laGAT0t2JyUg/edit?usp=sharing"",""Perf_mois!B13"")"),4.0) -> 4 | E13: 9

Sheet Graph4_evolution_CA_ventes
A1: ANNEE | B1: CA_HT | C1: VENTES
A2: 2020 | B2: =IFERROR(__xludf.DUMMYFUNCTION("IMPORTRANGE(""https://docs.google.com/spreadsheets/d/15-T8p6Spj94rgjtigS4K1Txxrtq2lA5cZX9vdvUiAsQ/edit?usp=sharing"",""Evolution_CA!B2"")"),303168.0) -> 303168 | C2: =IFERROR(__xludf.DUMMYFUNCTION("IMPORTRANGE(""https://docs.google.com/spreadsheets/d/15-T8p6Spj94rgjtigS4K1Txxrtq2lA5cZX9vdvUiAsQ/edit?usp=sharing"",""Evolution_CA!C2"")"),39.0) -> 39
A3: 2021 | B3: =IFERROR(__xludf.DUMMYFUNCTION("IMPORTRANGE(""https://docs.google.com/spreadsheets/d/15-T8p6Spj94rgjtigS4K1Txxrtq2lA5cZX9vdvUiAsQ/edit?usp=sharing"",""Evolution_CA!B3"")"),352327.0) -> 352327 | C3: =IFERROR(__xludf.DUMMYFUNCTION("IMPORTRANGE(""https://docs.google.com/spreadsheets/d/15-T8p6Spj94rgjtigS4K1Txxrtq2lA5cZX9vdvUiAsQ/edit?usp=sharing"",""Evolution_CA!C3"")"),46.0) -> 46
A4: 2022 | B4: =IFERROR(__xludf.DUMMYFUNCTION("IMPORTRANGE(""https://docs.google.com/spreadsheets/d/15-T8p6Spj94rgjtigS4K1Txxrtq2lA5cZX9vdvUiAsQ/edit?usp=sharing"",""Evolution_CA!B4"")"),277368.0) -> 277368 | C4: =IFERROR(__xludf.DUMMYFUNCTION("IMPORTRANGE(""https://docs.google.com/spreadsheets/d/15-T8p6Spj94rgjtigS4K1Txxrtq2lA5cZX9vdvUiAsQ/edit?usp=sharing"",""Evolution_CA!C4"")"),37.0) -> 37
A5: 2023 | B5: =IFERROR(__xludf.DUMMYFUNCTION("IMPORTRANGE(""https://docs.google.com/spreadsheets/d/15-T8p6Spj94rgjtigS4K1Txxrtq2lA5cZX9vdvUiAsQ/edit?usp=sharing"",""Evolution_CA!B5"")"),376353.0) -> 376353 | C5: =IFERROR(__xludf.DUMMYFUNCTION("IMPORTRANGE(""https://docs.google.com/spreadsheets/d/15-T8p6Spj94rgjtigS4K1Txxrtq2lA5cZX9vdvUiAsQ/edit?usp=sharing"",""Evolution_CA!C5"")"),46.0) -> 46

Sheet Graph5_repartition_CA_commissio
A1: ANNEE | B1: CA_HT
A2: CA_ENCAISSE | B2: =IFERROR(__xludf.DUMMYFUNCTION("IMPORTRANGE(""https://docs.google.com/spreadsheets/d/1zA5LDh046PMNVU8ONXHA9gKBkE8m_N5laGAT0t2JyUg/edit?usp=sharing"",""Perf_mois!E15"")"),273208.33) -> 273208.33
A3: COMMISSIONS | B3: =IFERROR(__xludf.DUMMYFUNCTION("IMPORTRANGE(""https://docs.google.com/spreadsheets/d/1zA5LDh046PMNVU8ONXHA9gKBkE8m_N5laGAT0t2JyUg/edit?usp=sharing"",""Perf_mois!D15"")"),88591.66666666666) -> 88591.667

Sheet Graph6_CA_source
A1: SOURCE | B1: NOMBRE_VENTES | C1: MONTANT_CA | D1: %_SUR_CA
A2: RESEAU_PERSO | B2: =IFERROR(__xludf.DUMMYFUNCTION("IMPORTRANGE(""https://docs.google.com/spreadsheets/d/1zA5LDh046PMNVU8ONXHA9gKBkE8m_N5laGAT0t2JyUg/edit?usp=sharing"",""Sources_ventes!B2"")"),25.0) -> 25 | C2: =IFERROR(__xludf.DUMMYFUNCTION("IMPORTRANGE(""https://docs.google.com/spreadsheets/d/1zA5LDh046PMNVU8ONXHA9gKBkE8m_N5laGAT0t2JyUg/edit?usp=sharing"",""Sources_ventes!C2"")"),205416.66333333333) -> 205416.66 | D2: =IFERROR(__xludf.DUMMYFUNCTION("IMPORTRANGE(""https://docs.google.com/spreadsheets/d/1zA5LDh046PMNVU8ONXHA9gKBkE8m_N5laGAT0t2JyUg/edit?usp=sharing"",""Sources_ventes!D2"")"),56.77630326862265) -> 56.776303
A3: NOTORIETE | B3: =IFERROR(__xludf.DUMMYFUNCTION("IMPORTRANGE(""https://docs.google.com/spreadsheets/d/1zA5LDh046PMNVU8ONXHA9gKBkE8m_N5laGAT0t2JyUg/edit?usp=sharing"",""Sources_ventes!B3"")"),6.0) -> 6 | C3: =IFERROR(__xludf.DUMMYFUNCTION("IMPORTRANGE(""https://docs.google.com/spreadsheets/d/1zA5LDh046PMNVU8ONXHA9gKBkE8m_N5laGAT0t2JyUg/edit?usp=sharing"",""Sources_ventes!C3"")"),40833.333333333336) -> 40833.333 | D3: =IFERROR(__xludf.DUMMYFUNCTION("IMPORTRANGE(""https://docs.google.com/spreadsheets/d/1zA5LDh046PMNVU8ONXHA9gKBkE8m_N5laGAT0t2JyUg/edit?usp=sharing"",""Sources_ventes!D3"")"),11.286161887655812) -> 11.286162
A4: CLIENTS_ACHETEUR_VENDEUR | B4: =IFERROR(__xludf.DUMMYFUNCTION("IMPORTRANGE(""https://docs.google.com/spreadsheets/d/1zA5LDh046PMNVU8ONXHA9gKBkE8m_N5laGAT0t2JyUg/edit?usp=sharing"",""Sources_ventes!B4"")"),3.0) -> 3 | C4: =IFERROR(__xludf.DUMMYFUNCTION("IMPORTRANGE(""https://docs.google.com/spreadsheets/d/1zA5LDh046PMNVU8ONXHA9gKBkE8m_N5laGAT0t2JyUg/edit?usp=sharing"",""Sources_ventes!C4"")"),23333.333333333336) -> 23333.333 | D4: =IFERROR(__xludf.DUMMYFUNCTION("IMPORTRANGE(""https://docs.google.com/spreadsheets/d/1zA5LDh046PMNVU8ONXHA9gKBkE8m_N5laGAT0t2JyUg/edit?usp=sharing"",""Sources_ventes!D4"")"),6.44923536437475) -> 6.4492354
A5: DIGITAL | B5: =IFERROR(__xludf.DUMMYFUNCTION("IMPORTRANGE(""https://docs.google.com/spreadsheets/d/1zA5LDh046PMNVU8ONXHA9gKBkE8m_N5laGAT0t2JyUg/edit?usp=sharing"",""Sources_ventes!B5"")"),12.0) -> 12 | C5: =IFERROR(__xludf.DUMMYFUNCTION("IMPORTRANGE(""https://docs.google.com/spreadsheets/d/1zA5LDh046PMNVU8ONXHA9gKBkE8m_N5laGAT0t2JyUg/edit?usp=sharing"",""Sources_ventes!C5"")"),92216.66666666669) -> 92216.667 | D5: =IFERROR(__xludf.DUMMYFUNCTION("IMPORTRANGE(""https://docs.google.com/spreadsheets/d/1zA5LDh046PMNVU8ONXHA9gKBkE8m_N5laGAT0t2JyUg/edit?usp=sharing"",""Sources_ventes!D5"")"),25.488299479346782) -> 25.488299
A6: RESEAU_PERSO | B6: =IFERROR(__xludf.DUMMYFUNCTION("IMPORTRANGE(""https://docs.google.com/spreadsheets/d/1zA5LDh046PMNVU8ONXHA9gKBkE8m_N5laGAT0t2JyUg/edit?usp=sharing"",""Sources_ventes!B9"")"),16.0) -> 16 | C6: =IFERROR(__xludf.DUMMYFUNCTION("IMPORTRANGE(""https://docs.google.com/spreadsheets/d/1zA5LDh046PMNVU8ONXHA9gKBkE8m_N5laGAT0t2JyUg/edit?usp=sharing"",""Sources_ventes!C9"")"),136249.99666666667) -> 136250 | D6: =C6/361800% -> 37.658927
A7: RESEAU_PERSO_RECO | B7: =IFERROR(__xludf.DUMMYFUNCTION("IMPORTRANGE(""https://docs.google.com/spreadsheets/d/1zA5LDh046PMNVU8ONXHA9gKBkE8m_N5laGAT0t2JyUg/edit?usp=sharing"",""Sources_ventes!B10"")"),5.0) -> 5 | C7: =IFERROR(__xludf.DUMMYFUNCTION("IMPORTRANGE(""https://docs.google.com/spreadsheets/d/1zA5LDh046PMNVU8ONXHA9gKBkE8m_N5laGAT0t2JyUg/edit?usp=sharing"",""Sources_ventes!C10"")"),37500.00000000001) -> 37500 | D7: =C7/361800% -> 10.364842
A8: RESEAU_PERSO_ANCIEN_CLIENT | B8: =IFERROR(__xludf.DUMMYFUNCTION("IMPORTRANGE(""https://docs.google.com/spreadsheets/d/1zA5LDh046PMNVU8ONXHA9gKBkE8m_N5laGAT0t2JyUg/edit?usp=sharing"",""Sources_ventes!B11"")"),3.0) -> 3 | C8: =IFERROR(__xludf.DUMMYFUNCTION("IMPORTRANGE(""https://docs.google.com/spreadsheets/d/1zA5LDh046PMNVU8ONXHA9gKBkE8m_N5laGAT0t2JyUg/edit?usp=sharing"",""Sources_ventes!C11"")"),24166.666666666668) -> 24166.667 | D8: =C8/361800% -> 6.6795651
A9: PHONING | B9: =IFERROR(__xludf.DUMMYFUNCTION("IMPORTRANGE(""https://docs.google.com/spreadsheets/d/1zA5LDh046PMNVU8ONXHA9gKBkE8m_N5laGAT0t2JyUg/edit?usp=sharing"",""Sources_ventes!B12"")"),1.0) -> 1 | C9: =IFERROR(__xludf.DUMMYFUNCTION("IMPORTRANGE(""https://docs.google.com/spreadsheets/d/1zA5LDh046PMNVU8ONXHA9gKBkE8m_N5laGAT0t2JyUg/edit?usp=sharing"",""Sources_ventes!C12"")"),7500.0) -> 7500 | D9: =C9/361800% -> 2.0729685
A10: PROSPECTION_TERRAIN | B10: =IFERROR(__xludf.DUMMYFUNCTION("IMPORTRANGE(""https://docs.google.com/spreadsheets/d/1zA5LDh046PMNVU8ONXHA9gKBkE8m_N5laGAT0t2JyUg/edit?usp=sharing"",""Sources_ventes!B13"")"),0.0) -> 0 | C10: =IFERROR(__xludf.DUMMYFUNCTION("IMPORTRANGE(""https://docs.google.com/spreadsheets/d/1zA5LDh046PMNVU8ONXHA9gKBkE8m_N5laGAT0t2JyUg/edit?usp=sharing"",""Sources_ventes!C13"")"),0.0) -> 0 | D10: =C10/361800% -> 0
A11: AGENCE_APPEL_NOTORIETE | B11: =IFERROR(__xludf.DUMMYFUNCTION("IMPORTRANGE(""https://docs.google.com/spreadsheets/d/1zA5LDh046PMNVU8ONXHA9gKBkE8m_N5laGAT0t2JyUg/edit?usp=sharing"",""Sources_ventes!B14"")"),3.0) -> 3 | C11: =IFERROR(__xludf.DUMMYFUNCTION("IMPORTRANGE(""https://docs.google.com/spreadsheets/d/1zA5LDh046PMNVU8ONXHA9gKBkE8m_N5laGAT0t2JyUg/edit?usp=sharing"",""Sources_ventes!C14"")"),15833.333333333336) -> 15833.333 | D11: =C11/361800% -> 4.3762668
A12: PANNEAU_VENTE | B12: =IFERROR(__xludf.DUMMYFUNCTION("IMPORTRANGE(""https://docs.google.com/spreadsheets/d/1zA5LDh046PMNVU8ONXHA9gKBkE8m_N5laGAT0t2JyUg/edit?usp=sharing"",""Sources_ventes!B15"")"),2.0) -> 2 | C12: =IFERROR(__xludf.DUMMYFUNCTION("IMPORTRANGE(""https://docs.google.com/spreadsheets/d/1zA5LDh046PMNVU8ONXHA9gKBkE8m_N5laGAT0t2JyUg/edit?usp=sharing"",""Sources_ventes!C15"")"),15000.0) -> 15000 | D12: =C12/361800% -> 4.145937
A13: AGENCE_PROXIMITE | B13: =IFERROR(__xludf.DUMMYFUNCTION("IMPORTRANGE(""https://docs.google.com/spreadsheets/d/1zA5LDh046PMNVU8ONXHA9gKBkE8m_N5laGAT0t2JyUg/edit?usp=sharing"",""Sources_ventes!B16"")"),1.0) -> 1 | C13: =IFERROR(__xludf.DUMMYFUNCTION("IMPORTRANGE(""https://docs.google.com/spreadsheets/d/1zA5LDh046PMNVU8ONXHA9gKBkE8m_N5laGAT0t2JyUg/edit?usp=sharing"",""Sources_ventes!C16"")"),10000.0) -> 10000 | D13: =C13/361800% -> 2.763958
A14: CLIENTS_ACHETEUR_VENDEUR | B14: =IFERROR(__xludf.DUMMYFUNCTION("IMPORTRANGE(""https://docs.google.com/spreadsheets/d/1zA5LDh046PMNVU8ONXHA9gKBkE8m_N5laGAT0t2JyUg/edit?usp=sharing"",""Sources_ventes!B17"")"),3.0) -> 3 | C14: =IFERROR(__xludf.DUMMYFUNCTION("IMPORTRANGE(""https://docs.google.com/spreadsheets/d/1zA5LDh046PMNVU8ONXHA9gKBkE8m_N5laGAT0t2JyUg/edit?usp=sharing"",""Sources_ventes!C17"")"),23333.333333333336) -> 23333.333 | D14: =C14/361800% -> 6.4492353
A15: AGENCE_DELEGATION_MANDAT | B15: =IFERROR(__xludf.DUMMYFUNCTION("IMPORTRANGE(""https://docs.google.com/spreadsheets/d/1zA5LDh046PMNVU8ONXHA9gKBkE8m_N5laGAT0t2JyUg/edit?usp=sharing"",""Sources_ventes!B18"")"),1.0) -> 1 | C15: =IFERROR(__xludf.DUMMYFUNCTION("IMPORTRANGE(""https://docs.google.com/spreadsheets/d/1zA5LDh046PMNVU8ONXHA9gKBkE8m_N5laGAT0t2JyUg/edit?usp=sharing"",""Sources_ventes!C18"")"),4000.0) -> 4000 | D15: =C15/361800% -> 1.1055832
A16: AGENCE_FORMULAIRE_ESTIMATION | B16: =IFERROR(__xludf.DUMMYFUNCTION("IMPORTRANGE(""https://docs.google.com/spreadsheets/d/1zA5LDh046PMNVU8ONXHA9gKBkE8m_N5laGAT0t2JyUg/edit?usp=sharing"",""Sources_ventes!B19"")"),5.0) -> 5 | C16: =IFERROR(__xludf.DUMMYFUNCTION("IMPORTRANGE(""https://docs.google.com/spreadsheets/d/1zA5LDh046PMNVU8ONXHA9gKBkE8m_N5laGAT0t2JyUg/edit?usp=sharing"",""Sources_ventes!C19"")"),35716.66666666667) -> 35716.667 | D16: =C16/361800% -> 9.8719366
A17: AGENCE_REALADVISOR | B17: =IFERROR(__xludf.DUMMYFUNCTION("IMPORTRANGE(""https://docs.google.com/spreadsheets/d/1zA5LDh046PMNVU8ONXHA9gKBkE8m_N5laGAT0t2JyUg/edit?usp=sharing"",""Sources_ventes!B20"")"),1.0) -> 1 | C17: =IFERROR(__xludf.DUMMYFUNCTION("IMPORTRANGE(""https://docs.google.com/spreadsheets/d/1zA5LDh046PMNVU8ONXHA9gKBkE8m_N5laGAT0t2JyUg/edit?usp=sharing"",""Sources_ventes!C20"")"),8333.333333333334) -> 8333.3333 | D17: =C17/361800% -> 2.3032983
A18: AGENCE_REFERENCEMENT_NATUREL_AVIS | B18: =IFERROR(__xludf.DUMMYFUNCTION("IMPORTRANGE(""https://docs.google.com/spreadsheets/d/1zA5LDh046PMNVU8ONXHA9gKBkE8m_N5laGAT0t2JyUg/edit?usp=sharing"",""Sources_ventes!B21"")"),5.0) -> 5 | C18: =IFERROR(__xludf.DUMMYFUNCTION("IMPORTRANGE(""https://docs.google.com/spreadsheets/d/1zA5LDh046PMNVU8ONXHA9gKBkE8m_N5laGAT0t2JyUg/edit?usp=sharing"",""Sources_ventes!C21"")"),44166.66666666667) -> 44166.667 | D18: =C18/361800% -> 12.207481

Sheet Graph7_ventes_bilan
A1: CRITERES | B1: COL_1
A2: VENTES_AJOUTE_2022 | B2: =IFERROR(__xludf.DUMMYFUNCTION("IMPORTRANGE(""https://docs.google.com/spreadsheets/d/1zA5LDh046PMNVU8ONXHA9gKBkE8m_N5laGAT0t2JyUg/edit?usp=sharing"",""Perf_globales!F3"")"),10.0) -> 10
A3: VENTES_REELLES_2023 | B3: =IFERROR(__xludf.DUMMYFUNCTION("IMPORTRANGE(""https://docs.google.com/spreadsheets/d/1zA5LDh046PMNVU8ONXHA9gKBkE8m_N5laGAT0t2JyUg/edit?usp=sharing"",""Perf_globales!I3"")"),36.0) -> 36

Sheet Graph8_ventes_travaillees
A1: CRITERES | B1: COL_1
A2: VENTES_REELLES_2023 | B2: =IFERROR(__xludf.DUMMYFUNCTION("IMPORTRANGE(""https://docs.google.com/spreadsheets/d/1zA5LDh046PMNVU8ONXHA9gKBkE8m_N5laGAT0t2JyUg/edit?usp=sharing"",""Perf_globales!I3"")"),36.0) -> 36
A3: VENTES_REPORTEES_2024 | B3: =IFERROR(__xludf.DUMMYFUNCTION("IMPORTRANGE(""https://docs.google.com/spreadsheets/d/1zA5LDh046PMNVU8ONXHA9gKBkE8m_N5laGAT0t2JyUg/edit?usp=sharing"",""Perf_globales!L3"")"),7.0) -> 7
A4: VENTES_TRAVAILLE | B4: =IFERROR(__xludf.DUMMYFUNCTION("IMPORTRANGE(""https://docs.google.com/spreadsheets/d/1zA5LDh046PMNVU8ONXHA9gKBkE8m_N5laGAT0t2JyUg/edit?usp=sharing"",""Perf_globales!O3"")"),43.0) -> 43
A5: MANDATS_TOTAL | B5: 93
A6: TAUX_MANDATS_VENDUS | B6: 47.3

Sheet Graph9_ventes_source_detail
A1: SOURCE | B1: RESEAU_PERSO | C1: DIGITAL | D1: NOTORIETE | E1: CLIENTS_ACHETEUR_VENDEUR
A2: RESEAU_PERSO | B2: =IFERROR(__xludf.DUMMYFUNCTION("IMPORTRANGE(""https://docs.google.com/spreadsheets/d/1zA5LDh046PMNVU8ONXHA9gKBkE8m_N5laGAT0t2JyUg/edit?usp=sharing"",""Sources_ventes!B9"")"),16.0) -> 16 | C2: 0 | D2: 0 | E2: 0
A3: RESEAU_PERSO_RECO | B3: =IFERROR(__xludf.DUMMYFUNCTION("IMPORTRANGE(""https://docs.google.com/spreadsheets/d/1zA5LDh046PMNVU8ONXHA9gKBkE8m_N5laGAT0t2JyUg/edit?usp=sharing"",""Sources_ventes!B10"")"),5.0) -> 5 | C3: 0 | D3: 0 | E3: 0
A4: RESEAU_PERSO_ANCIEN_CLIENT | B4: =IFERROR(__xludf.DUMMYFUNCTION("IMPORTRANGE(""https://docs.google.com/spreadsheets/d/1zA5LDh046PMNVU8ONXHA9gKBkE8m_N5laGAT0t2JyUg/edit?usp=sharing"",""Sources_ventes!B11"")"),3.0) -> 3 | C4: 0 | D4: 0 | E4: 0
A5: PHONING | B5: =IFERROR(__xludf.DUMMYFUNCTION("IMPORTRANGE(""https://docs.google.com/spreadsheets/d/1zA5LDh046PMNVU8ONXHA9gKBkE8m_N5laGAT0t2JyUg/edit?usp=sharing"",""Sources_ventes!B12"")"),1.0) -> 1 | C5: 0 | D5: 0 | E5: 0
A6: PROSPECTION_TERRAIN | B6: =IFERROR(__xludf.DUMMYFUNCTION("IMPORTRANGE(""https://docs.google.com/spreadsheets/d/1zA5LDh046PMNVU8ONXHA9gKBkE8m_N5laGAT0t2JyUg/edit?usp=sharing"",""Sources_ventes!B13"")"),0.0) -> 0 | C6: 0 | D6: 0 | E6: 0
A7: AGENCE_DELEGATION_MANDAT | B7: 0 | C7: 1 | D7: 0 | E7: 0
A8: AGENCE_FORMULAIRE_ESTIMATION | B8: 0 | C8: 5 | D8: 0 | E8: 0
A9: AGENCE_REALADVISOR | B9: 0 | C9: 1 | D9: 0 | E9: 0
A10: AGENCE_REFERENCEMENT_NATUREL_AVIS | B10: 0 | C10: 5 | D10: 0 | E10: 0
A11: AGENCE_APPEL_NOTORIETE | B11: 0 | C11: 0 | D11: 3 | E11: 0
A12: PANNEAU_VENTE | B12: 0 | C12: 0 | D12: 2 | E12: 0
A13: AGENCE_PROXIMITE | B13: 0 | C13: 0 | D13: 1 | E13: 0
A14: CLIENTS_ACHETEUR_VENDEUR | B14: 0 | C14: 0 | D14: 0 | E14: 3

Sheet Graph10_CA_source_detail
A1: SOURCE | B1: RESEAU_PERSO | C1: DIGITAL | D1: NOTORIETE | E1: CLIENTS_ACHETEUR_VENDEUR
A2: RESEAU_PERSO | B2: =IFERROR(__xludf.DUMMYFUNCTION("IMPORTRANGE(""https://docs.google.com/spreadsheets/d/1zA5LDh046PMNVU8ONXHA9gKBkE8m_N5laGAT0t2JyUg/edit?usp=sharing"",""Sources_ventes!C9"")"),136249.99666666667) -> 136250 | C2: 0 | D2: 0 | E2: 0
A3: RESEAU_PERSO_RECO | B3: =IFERROR(__xludf.DUMMYFUNCTION("IMPORTRANGE(""https://docs.google.com/spreadsheets/d/1zA5LDh046PMNVU8ONXHA9gKBkE8m_N5laGAT0t2JyUg/edit?usp=sharing"",""Sources_ventes!C10"")"),37500.00000000001) -> 37500 | C3: 0 | D3: 0 | E3: 0
A4: RESEAU_PERSO_ANCIEN_CLIENT | B4: =IFERROR(__xludf.DUMMYFUNCTION("IMPORTRANGE(""https://docs.google.com/spreadsheets/d/1zA5LDh046PMNVU8ONXHA9gKBkE8m_N5laGAT0t2JyUg/edit?usp=sharing"",""Sources_ventes!C11"")"),24166.666666666668) -> 24166.667 | C4: 0 | D4: 0 | E4: 0
A5: PHONING | B5: =IFERROR(__xludf.DUMMYFUNCTION("IMPORTRANGE(""https://docs.google.com/spreadsheets/d/1zA5LDh046PMNVU8ONXHA9gKBkE8m_N5laGAT0t2JyUg/edit?usp=sharing"",""Sources_ventes!C12"")"),7500.0) -> 7500 | C5: 0 | D5: 0 | E5: 0
A6: PROSPECTION_TERRAIN | B6: =IFERROR(__xludf.DUMMYFUNCTION("IMPORTRANGE(""https://docs.google.com/spreadsheets/d/1zA5LDh046PMNVU8ONXHA9gKBkE8m_N5laGAT0t2JyUg/edit?usp=sharing"",""Sources_ventes!B13"")"),0.0) -> 0 | C6: 0 | D6: 0 | E6: 0
A7: AGENCE_DELEGATION_MANDAT | B7: 0 | C7: =IFERROR(__xludf.DUMMYFUNCTION("IMPORTRANGE(""https://docs.google.com/spreadsheets/d/1zA5LDh046PMNVU8ONXHA9gKBkE8m_N5laGAT0t2JyUg/edit?usp=sharing"",""Sources_ventes!C18"")"),4000.0) -> 4000 | D7: 0 | E7: 0
A8: AGENCE_FORMULAIRE_ESTIMATION | B8: 0 | C8: =IFERROR(__xludf.DUMMYFUNCTION("IMPORTRANGE(""https://docs.google.com/spreadsheets/d/1zA5LDh046PMNVU8ONXHA9gKBkE8m_N5laGAT0t2JyUg/edit?usp=sharing"",""Sources_ventes!C19"")"),35716.66666666667) -> 35716.667 | D8: 0 | E8: 0
A9: AGENCE_REALADVISOR | B9: 0 | C9: =IFERROR(__xludf.DUMMYFUNCTION("IMPORTRANGE(""https://docs.google.com/spreadsheets/d/1zA5LDh046PMNVU8ONXHA9gKBkE8m_N5laGAT0t2JyUg/edit?usp=sharing"",""Sources_ventes!C20"")"),8333.333333333334) -> 8333.3333 | D9: 0 | E9: 0
A10: AGENCE_REFERENCEMENT_NATUREL_AVIS | B10: 0 | C10: =IFERROR(__xludf.DUMMYFUNCTION("IMPORTRANGE(""https://docs.google.com/spreadsheets/d/1zA5LDh046PMNVU8ONXHA9gKBkE8m_N5laGAT0t2JyUg/edit?usp=sharing"",""Sources_ventes!C21"")"),44166.66666666667) -> 44166.667 | D10: 0 | E10: 0
A11: AGENCE_APPEL_NOTORIETE | B11: 0 | C11: 0 | D11: =IFERROR(__xludf.DUMMYFUNCTION("IMPORTRANGE(""https://docs.google.com/spreadsheets/d/1zA5LDh046PMNVU8ONXHA9gKBkE8m_N5laGAT0t2JyUg/edit?usp=sharing"",""Sources_ventes!C14"")"),15833.333333333336) -> 15833.333 | E11: 0
A12: PANNEAU_VENTE | B12: 0 | C12: 0 | D12: =IFERROR(__xludf.DUMMYFUNCTION("IMPORTRANGE(""https://docs.google.com/spreadsheets/d/1zA5LDh046PMNVU8ONXHA9gKBkE8m_N5laGAT0t2JyUg/edit?usp=sharing"",""Sources_ventes!C15"")"),15000.0) -> 15000 | E12: 0
A13: AGENCE_PROXIMITE | B13: 0 | C13: 0 | D13: =IFERROR(__xludf.DUMMYFUNCTION("IMPORTRANGE(""https://docs.google.com/spreadsheets/d/1zA5LDh046PMNVU8ONXHA9gKBkE8m_N5laGAT0t2JyUg/edit?usp=sharing"",""Sources_ventes!C16"")"),10000.0) -> 10000 | E13: 0
A14: CLIENTS_ACHETEUR_VENDEUR | B14: 0 | C14: 0 | D14: 0 | E14: =IFERROR(__xludf.DUMMYFUNCTION("IMPORTRANGE(""https://docs.google.com/spreadsheets/d/1zA5LDh046PMNVU8ONXHA9gKBkE8m_N5laGAT0t2JyUg/edit?usp=sharing"",""Sources_ventes!C17"")"),23333.333333333336) -> 23333.333

Sheet Graph11_depenses_mois
A1: MOIS | B1: DEPENSES_COURANTES | C1: DEPENSES_EXCEPTIONNELLES | D1: DEPENSES_NOTES_DE_FRAIS | E1: DEPENSES_COMMISSIONS_HT | F1: DEPENSES_TVA | G1: DEPENSES_SALAIRES
A2: JANVIER | B2: =1900+176.4+7.99+3000+256.92+241.64+9.99+294.55+877.46+372.69+106.92+50.97+1400+98.46+134.26+48+38.31+53.9+924.33+6.08+450+74.4+2.46+346+1.99+7.99+851.7+2257+400+557 -> 14947.41 | C2: =50.11+27+27+27+27+299.99+90+2276.02+418.8+418.8+5000+812.4+120+250+400 -> 10244.12 | D2: =14.32+10+6+58.35+26.9+57+2.8+57.6+65+51+54.4+23+27.3+99+44.2 -> 596.87 | E2: =5000 -> 5000 | F2: 5020 | G2: =60+521+7+110.74+52.83+129.48+1341.38 -> 2222.43
A3: FEVRIER | B3: =1900+300+250+514.19+877.46+372.69+2500+226.2+9.99+100.8+851.7+50.97+1400+82.83+48+134.26+38.31+924.33+450+418.8+46.05+346+2.46+74.4+1.99+60+541.11+2257+400+526 -> 15705.54 | C3: =20+3021+276+30.14 -> 3347.14 | D3: =11.4+16.48+86.2+190.13+190.13+12.3+22.88+149.9+59.9+13.78+14.59+3.7+32.85+14.45+67.5+31+41.8 -> 958.99 | E3: =4000+4438.19+4500 -> 12938.19 | F3: 2330 | G3: =60+339+7+42.89 -> 448.89
A4: MARS | B4: =2200+2500+269.44+400.38+851.7+7.99+60+877.46+372.69+252.6+9.99+50.97+100.8+348+1400+82.41+11.85+134.26+38.31+924.33+450+60+30+346+541.11+1.99+2.46+74.4+3300+7.99+500 -> 16207.13 | C4: =174+270+410+1029.6+47.66+33.8+885+132 -> 2982.06 | D4: =7.38+43.1+41.68+33.8+14.7+38.39+49.3+90.5+19.7+10+19.7+12.88+18.6+29.5+28.5+77.6 -> 535.33 | E4: =2500 -> 2500 | F4: =3821+6+11023 -> 14850 | G4: =1093.94+60+930+42.68 -> 2126.62
A5: AVRIL | B5: =2250+294.55+418.8+23.66+9.99+176.4+265.8+2200+877.46+372.69+1400+81.36+50.97+134.26+133.2+851.7+38.31+137.39+269.44+269.44+924.33+450+30+181.48+541.11+2.46+74.4+1.99+561.04+28.8+59.8 -> 13110.83 | C5: =367.48+1347.06+11239.62+190+336.76+27+27+27+27+27+27+27+27+5000+750.6 -> 19447.52 | D5: =73+39.3+22.72+541.85+7.4+15.76+24.4+100.46+18.3+268.1+43.7+7.83+46.9+15.98+44+25 -> 1294.7 | E5: =4000+5000+6000 -> 15000 | F5: 5487 | G5: =1155.25+90+301+25.31+60.12+68.54+207.57+42.68 -> 1950.47
A6: MAI | B6: =100.8+2250+3300+8.99+27.02+500+1750+226.2+9.99+877.46+372.69+118.8+150+1400+81.99+50+50.97+134.26+851.7+38.31+250+250+924.33+450+30+541.11+74.4+2.46+3300+466.53+8.99+1.99+56.07+1.93+2500 -> 21156.99 | C6: =2250+44+120+350+300+2874+259.2 -> 6197.2 | D6: =20.4+176.4+10.62+6.86+21.08+20.9+35.48+37+4.5+60+59.2 -> 452.44 | E6: 0 | F6: 5443 | G6: =1321.24+60+345+1287.54+64.04 -> 3077.82
A7: JUIN | B7: =2250+1.92+55.76+483.91+67.45+9.99+877.46+372.69+226.2+1.47+40.29+118.8+50.97+1400+851.7+134.26+41.78+269.44+269.44+38.31+924.33+450+30+541.11+86.74+466.53+1.99+120+3300+8.99+500 -> 13991.53 | C7: =58+17+528+18+27+27+27+27+27+27+136.78 -> 919.78 | D7: =120.5+8.32+65.4+75.63+100+25.8+42.5+67.55+41.6+27.3 -> 574.6 | E7: 0 | F7: 809 | G7: =336+42.68 -> 378.68
A8: JUILLET | B8: =2250+294.55+185.4+2500+24.05+9.99+67.45+252+100.8+372.69+877.46+1400+81.15+118.8+134.26+50.97+50+851.7+38.31+924.33+30+541.11+86.74+466.53+1.99+3300+2500 -> 17510.28 | C8: =353.31+180+199.99+650+315+36+3502.93+92.6 -> 5329.83 | D8: =16.2+12.8+228+259+313.68+33.4+415.05+48.95+9+116+69+15.07+19+45+56+119.6+13.5+41.8 -> 1831.05 | E8: =6000+6000+4200-(2700) -> 13500 | F8: 7217 | G8: =976.72+1837.98+257+25.58+51.13+66.83+68.54 -> 3283.78
A9: AOUT | B9: =9.59+199.8+67.45+118.8+50+851.7+134.26+541.11+8.99+3300+37.9+500+2250+373+27.11+1.43+39.08+9.99+372.69+877.46+50.97+1000+9.12+0.56+1400+81.36+38.31+60+30+1.99+84+2.74+466+500+1091.52 -> 14586.93 | C9: =3642+27+27+27+27+35+27+27+158+87.1+689+139 -> 4912.1 | D9: =145+564+41.6+17.4+204+154.7+35+7.65+51.2+62.25+47.3+66.9+38.4+5.5+57.5+70.8 -> 1569.2 | E9: =4800+9000+2880-(2780) -> 13900 | F9: 5774 | G9: 2413
A10: SEPTEMBRE | B10: 19043 | C10: 7644 | D10: 2450 | E10: 0 | F10: 4171 | G10: 0
A11: OCTOBRE | B11: 18241 | C11: 12180 | D11: 944 | E11: =6000+6000+6000-(3000) -> 15000 | F11: 12155 | G11: 0
A12: NOVEMBRE | B12: 20350 | C12: 17864 | D12: 644 | E12: =6100-(600) -> 5500 | F12: 0 | G12: 0
A13: DECEMBRE | B13: 15155 | C13: 14895 | D13: 634 | E13: =4200-(700) -> 3500 | F13: 0 | G13: 0

Sheet Graph12_ventes_agents_bilan
A1: CRITERES | B1: COL_1
A2: VENTES_AGENT_BILAN_2023_ALEX | B2: =IFERROR(__xludf.DUMMYFUNCTION("IMPORTRANGE(""https://docs.google.com/spreadsheets/d/1zA5LDh046PMNVU8ONXHA9gKBkE8m_N5laGAT0t2JyUg/edit?usp=sharing"",""Perf_agents!B2"")"),26.0) -> 26
A3: VENTES_AGENT_BILAN_2023_LISA | B3: =IFERROR(__xludf.DUMMYFUNCTION("IMPORTRANGE(""https://docs.google.com/spreadsheets/d/1zA5LDh046PMNVU8ONXHA9gKBkE8m_N5laGAT0t2JyUg/edit?usp=sharing"",""Perf_agents!B3"")"),19.0) -> 19
A4: VENTES_AGENT_BILAN_2023_AYLIN | B4: =IFERROR(__xludf.DUMMYFUNCTION("IMPORTRANGE(""https://docs.google.com/spreadsheets/d/1zA5LDh046PMNVU8ONXHA9gKBkE8m_N5laGAT0t2JyUg/edit?usp=sharing"",""Perf_agents!B4"")"),1.0) -> 1

Sheet Graph13_CA_agents_bilan
A1: CRITERES | B1: COL_1
A2: CA_HT_BILAN_ALEX | B2: =IFERROR(__xludf.DUMMYFUNCTION("IMPORTRANGE(""https://docs.google.com/spreadsheets/d/1zA5LDh046PMNVU8ONXHA9gKBkE8m_N5laGAT0t2JyUg/edit?usp=sharing"",""Perf_agents!C2"")"),206966.6633333333) -> 206966.66
A3: CA_HT_BILAN_LISA | B3: =IFERROR(__xludf.DUMMYFUNCTION("IMPORTRANGE(""https://docs.google.com/spreadsheets/d/1zA5LDh046PMNVU8ONXHA9gKBkE8m_N5laGAT0t2JyUg/edit?usp=sharing"",""Perf_agents!C3"")"),145666.6666666667) -> 145666.67
A4: CA_HT_BILAN_AYLIN | B4: =IFERROR(__xludf.DUMMYFUNCTION("IMPORTRANGE(""https://docs.google.com/spreadsheets/d/1zA5LDh046PMNVU8ONXHA9gKBkE8m_N5laGAT0t2JyUg/edit?usp=sharing"",""Perf_agents!C4"")"),9166.0) -> 9166

Sheet Graph14_perf_mois_agents
A1: MOIS_2023 | B1: NB_VENTES_BILAN_2023_ALEX | C1: NB_VENTES_BILAN_2023_LISA | D1: HONO_HT_BILAN_2023_ALEX | E1: HONO_HT_BILAN_2023_LISA | F1: COM_AGENT_HT_2023_ALEX | G1: COM_AGENT_HT_2023_LISA | H1: COM_RESIDE_ENCAISSEE_HT_2023_ALEX | I1: COM_RESIDE_ENCAISSEE_HT_2023
A2: JANVIER | B2: =IFERROR(__xludf.DUMMYFUNCTION("IMPORTRANGE(""https://docs.google.com/spreadsheets/d/1zA5LDh046PMNVU8ONXHA9gKBkE8m_N5laGAT0t2JyUg/edit?usp=sharing"",""Perf_agents!B9"")"),1.0) -> 1 | C2: =IFERROR(__xludf.DUMMYFUNCTION("IMPORTRANGE(""https://docs.google.com/spreadsheets/d/1zA5LDh046PMNVU8ONXHA9gKBkE8m_N5laGAT0t2JyUg/edit?usp=sharing"",""Perf_agents!B26"")"),1.0) -> 1 | D2: =IFERROR(__xludf.DUMMYFUNCTION("IMPORTRANGE(""https://docs.google.com/spreadsheets/d/1zA5LDh046PMNVU8ONXHA9gKBkE8m_N5laGAT0t2JyUg/edit?usp=sharing"",""Perf_agents!C9"")"),8333.333333333334) -> 8333.3333 | E2: =IFERROR(__xludf.DUMMYFUNCTION("IMPORTRANGE(""https://docs.google.com/spreadsheets/d/1zA5LDh046PMNVU8ONXHA9gKBkE8m_N5laGAT0t2JyUg/edit?usp=sharing"",""Perf_agents!C26"")"),8333.333333333334) -> 8333.3333 | F2: =IFERROR(__xludf.DUMMYFUNCTION("IMPORTRANGE(""https://docs.google.com/spreadsheets/d/1zA5LDh046PMNVU8ONXHA9gKBkE8m_N5laGAT0t2JyUg/edit?usp=sharing"",""Perf_agents!D9"")"),0.0) -> 0 | G2: =IFERROR(__xludf.DUMMYFUNCTION("IMPORTRANGE(""https://docs.google.com/spreadsheets/d/1zA5LDh046PMNVU8ONXHA9gKBkE8m_N5laGAT0t2JyUg/edit?usp=sharing"",""Perf_agents!D26"")"),5000.0) -> 5000 | H2: =D2-F2 -> 8333.3333 | I2: =E2-G2 -> 3333.3333
A3: FEVRIER | B3: =IFERROR(__xludf.DUMMYFUNCTION("IMPORTRANGE(""https://docs.google.com/spreadsheets/d/1zA5LDh046PMNVU8ONXHA9gKBkE8m_N5laGAT0t2JyUg/edit?usp=sharing"",""Perf_agents!B10"")"),1.0) -> 1 | C3: =IFERROR(__xludf.DUMMYFUNCTION("IMPORTRANGE(""https://docs.google.com/spreadsheets/d/1zA5LDh046PMNVU8ONXHA9gKBkE8m_N5laGAT0t2JyUg/edit?usp=sharing"",""Perf_agents!B27"")"),3.0) -> 3 | D3: =IFERROR(__xludf.DUMMYFUNCTION("IMPORTRANGE(""https://docs.google.com/spreadsheets/d/1zA5LDh046PMNVU8ONXHA9gKBkE8m_N5laGAT0t2JyUg/edit?usp=sharing"",""Perf_agents!C10"")"),6666.666666666667) -> 6666.6667 | E3: =IFERROR(__xludf.DUMMYFUNCTION("IMPORTRANGE(""https://docs.google.com/spreadsheets/d/1zA5LDh046PMNVU8ONXHA9gKBkE8m_N5laGAT0t2JyUg/edit?usp=sharing"",""Perf_agents!C27"")"),22500.0) -> 22500 | F3: =IFERROR(__xludf.DUMMYFUNCTION("IMPORTRANGE(""https://docs.google.com/spreadsheets/d/1zA5LDh046PMNVU8ONXHA9gKBkE8m_N5laGAT0t2JyUg/edit?usp=sharing"",""Perf_agents!D9"")"),0.0) -> 0 | G3: =IFERROR(__xludf.DUMMYFUNCTION("IMPORTRANGE(""https://docs.google.com/spreadsheets/d/1zA5LDh046PMNVU8ONXHA9gKBkE8m_N5laGAT0t2JyUg/edit?usp=sharing"",""Perf_agents!D27"")"),13500.0) -> 13500 | H3: =D3-F3 -> 6666.6667 | I3: =E3-G3 -> 9000
A4: MARS | B4: =IFERROR(__xludf.DUMMYFUNCTION("IMPORTRANGE(""https://docs.google.com/spreadsheets/d/1zA5LDh046PMNVU8ONXHA9gKBkE8m_N5laGAT0t2JyUg/edit?usp=sharing"",""Perf_agents!B11"")"),4.0) -> 4 | C4: =IFERROR(__xludf.DUMMYFUNCTION("IMPORTRANGE(""https://docs.google.com/spreadsheets/d/1zA5LDh046PMNVU8ONXHA9gKBkE8m_N5laGAT0t2JyUg/edit?usp=sharing"",""Perf_agents!B28"")"),2.0) -> 2 | D4: =IFERROR(__xludf.DUMMYFUNCTION("IMPORTRANGE(""https://docs.google.com/spreadsheets/d/1zA5LDh046PMNVU8ONXHA9gKBkE8m_N5laGAT0t2JyUg/edit?usp=sharing"",""Perf_agents!C11"")"),17916.663333333334) -> 17916.663 | E4: =IFERROR(__xludf.DUMMYFUNCTION("IMPORTRANGE(""https://docs.google.com/spreadsheets/d/1zA5LDh046PMNVU8ONXHA9gKBkE8m_N5laGAT0t2JyUg/edit?usp=sharing"",""Perf_agents!C28"")"),10833.333333333334) -> 10833.333 | F4: =IFERROR(__xludf.DUMMYFUNCTION("IMPORTRANGE(""https://docs.google.com/spreadsheets/d/1zA5LDh046PMNVU8ONXHA9gKBkE8m_N5laGAT0t2JyUg/edit?usp=sharing"",""Perf_agents!D9"")"),0.0) -> 0 | G4: =IFERROR(__xludf.DUMMYFUNCTION("IMPORTRANGE(""https://docs.google.com/spreadsheets/d/1zA5LDh046PMNVU8ONXHA9gKBkE8m_N5laGAT0t2JyUg/edit?usp=sharing"",""Perf_agents!D28"")"),6500.0) -> 6500 | H4: =D4-F4 -> 17916.663 | I4: =E4-G4 -> 4333.3333
A5: AVRIL | B5: =IFERROR(__xludf.DUMMYFUNCTION("IMPORTRANGE(""https://docs.google.com/spreadsheets/d/1zA5LDh046PMNVU8ONXHA9gKBkE8m_N5laGAT0t2JyUg/edit?usp=sharing"",""Perf_agents!B12"")"),1.0) -> 1 | C5: =IFERROR(__xludf.DUMMYFUNCTION("IMPORTRANGE(""https://docs.google.com/spreadsheets/d/1zA5LDh046PMNVU8ONXHA9gKBkE8m_N5laGAT0t2JyUg/edit?usp=sharing"",""Perf_agents!B29"")"),2.0) -> 2 | D5: =IFERROR(__xludf.DUMMYFUNCTION("IMPORTRANGE(""https://docs.google.com/spreadsheets/d/1zA5LDh046PMNVU8ONXHA9gKBkE8m_N5laGAT0t2JyUg/edit?usp=sharing"",""Perf_agents!C12"")"),4050.0) -> 4050 | E5: =IFERROR(__xludf.DUMMYFUNCTION("IMPORTRANGE(""https://docs.google.com/spreadsheets/d/1zA5LDh046PMNVU8ONXHA9gKBkE8m_N5laGAT0t2JyUg/edit?usp=sharing"",""Perf_agents!C29"")"),18333.333333333336) -> 18333.333 | F5: =IFERROR(__xludf.DUMMYFUNCTION("IMPORTRANGE(""https://docs.google.com/spreadsheets/d/1zA5LDh046PMNVU8ONXHA9gKBkE8m_N5laGAT0t2JyUg/edit?usp=sharing"",""Perf_agents!D9"")"),0.0) -> 0 | G5: =IFERROR(__xludf.DUMMYFUNCTION("IMPORTRANGE(""https://docs.google.com/spreadsheets/d/1zA5LDh046PMNVU8ONXHA9gKBkE8m_N5laGAT0t2JyUg/edit?usp=sharing"",""Perf_agents!D29"")"),11000.0) -> 11000 | H5: =D5-F5 -> 4050 | I5: =E5-G5 -> 7333.3333
A6: MAI | B6: =IFERROR(__xludf.DUMMYFUNCTION("IMPORTRANGE(""https://docs.google.com/spreadsheets/d/1zA5LDh046PMNVU8ONXHA9gKBkE8m_N5laGAT0t2JyUg/edit?usp=sharing"",""Perf_agents!B13"")"),2.0) -> 2 | C6: =IFERROR(__xludf.DUMMYFUNCTION("IMPORTRANGE(""https://docs.google.com/spreadsheets/d/1zA5LDh046PMNVU8ONXHA9gKBkE8m_N5laGAT0t2JyUg/edit?usp=sharing"",""Perf_agents!B30"")"),0.0) -> 0 | D6: =IFERROR(__xludf.DUMMYFUNCTION("IMPORTRANGE(""https://docs.google.com/spreadsheets/d/1zA5LDh046PMNVU8ONXHA9gKBkE8m_N5laGAT0t2JyUg/edit?usp=sharing"",""Perf_agents!C13"")"),12500.0) -> 12500 | E6: =IFERROR(__xludf.DUMMYFUNCTION("IMPORTRANGE(""https://docs.google.com/spreadsheets/d/1zA5LDh046PMNVU8ONXHA9gKBkE8m_N5laGAT0t2JyUg/edit?usp=sharing"",""Perf_agents!C30"")"),0.0) -> 0 | F6: =IFERROR(__xludf.DUMMYFUNCTION("IMPORTRANGE(""https://docs.google.com/spreadsheets/d/1zA5LDh046PMNVU8ONXHA9gKBkE8m_N5laGAT0t2JyUg/edit?usp=sharing"",""Perf_agents!D9"")"),0.0) -> 0 | G6: =IFERROR(__xludf.DUMMYFUNCTION("IMPORTRANGE(""https://docs.google.com/spreadsheets/d/1zA5LDh046PMNVU8ONXHA9gKBkE8m_N5laGAT0t2JyUg/edit?usp=sharing"",""Perf_agents!D30"")"),0.0) -> 0 | H6: =D6-F6 -> 12500 | I6: =E6-G6 -> 0
A7: JUIN | B7: =IFERROR(__xludf.DUMMYFUNCTION("IMPORTRANGE(""https://docs.google.com/spreadsheets/d/1zA5LDh046PMNVU8ONXHA9gKBkE8m_N5laGAT0t2JyUg/edit?usp=sharing"",""Perf_agents!B14"")"),2.0) -> 2 | C7: =IFERROR(__xludf.DUMMYFUNCTION("IMPORTRANGE(""https://docs.google.com/spreadsheets/d/1zA5LDh046PMNVU8ONXHA9gKBkE8m_N5laGAT0t2JyUg/edit?usp=sharing"",""Perf_agents!B31"")"),3.0) -> 3 | D7: =IFERROR(__xludf.DUMMYFUNCTION("IMPORTRANGE(""https://docs.google.com/spreadsheets/d/1zA5LDh046PMNVU8ONXHA9gKBkE8m_N5laGAT0t2JyUg/edit?usp=sharing"",""Perf_agents!C14"")"),15000.000000000002) -> 15000 | E7: =IFERROR(__xludf.DUMMYFUNCTION("IMPORTRANGE(""https://docs.google.com/spreadsheets/d/1zA5LDh046PMNVU8ONXHA9gKBkE8m_N5laGAT0t2JyUg/edit?usp=sharing"",""Perf_agents!C31"")"),22500.0) -> 22500 | F7: =IFERROR(__xludf.DUMMYFUNCTION("IMPORTRANGE(""https://docs.google.com/spreadsheets/d/1zA5LDh046PMNVU8ONXHA9gKBkE8m_N5laGAT0t2JyUg/edit?usp=sharing"",""Perf_agents!D9"")"),0.0) -> 0 | G7: =IFERROR(__xludf.DUMMYFUNCTION("IMPORTRANGE(""https://docs.google.com/spreadsheets/d/1zA5LDh046PMNVU8ONXHA9gKBkE8m_N5laGAT0t2JyUg/edit?usp=sharing"",""Perf_agents!D31"")"),13500.0) -> 13500 | H7: =D7-F7 -> 15000 | I7: =E7-G7 -> 9000
A8: JUILLET | B8: =IFERROR(__xludf.DUMMYFUNCTION("IMPORTRANGE(""https://docs.google.com/spreadsheets/d/1zA5LDh046PMNVU8ONXHA9gKBkE8m_N5laGAT0t2JyUg/edit?usp=sharing"",""Perf_agents!B15"")"),5.0) -> 5 | C8: =IFERROR(__xludf.DUMMYFUNCTION("IMPORTRANGE(""https://docs.google.com/spreadsheets/d/1zA5LDh046PMNVU8ONXHA9gKBkE8m_N5laGAT0t2JyUg/edit?usp=sharing"",""Perf_agents!B32"")"),1.0) -> 1 | D8: =IFERROR(__xludf.DUMMYFUNCTION("IMPORTRANGE(""https://docs.google.com/spreadsheets/d/1zA5LDh046PMNVU8ONXHA9gKBkE8m_N5laGAT0t2JyUg/edit?usp=sharing"",""Perf_agents!C15"")"),70833.33333333333) -> 70833.333 | E8: =IFERROR(__xludf.DUMMYFUNCTION("IMPORTRANGE(""https://docs.google.com/spreadsheets/d/1zA5LDh046PMNVU8ONXHA9gKBkE8m_N5laGAT0t2JyUg/edit?usp=sharing"",""Perf_agents!C32"")"),4000.0) -> 4000 | F8: =IFERROR(__xludf.DUMMYFUNCTION("IMPORTRANGE(""https://docs.google.com/spreadsheets/d/1zA5LDh046PMNVU8ONXHA9gKBkE8m_N5laGAT0t2JyUg/edit?usp=sharing"",""Perf_agents!D9"")"),0.0) -> 0 | G8: =IFERROR(__xludf.DUMMYFUNCTION("IMPORTRANGE(""https://docs.google.com/spreadsheets/d/1zA5LDh046PMNVU8ONXHA9gKBkE8m_N5laGAT0t2JyUg/edit?usp=sharing"",""Perf_agents!D32"")"),2400.0) -> 2400 | H8: =D8-F8 -> 70833.333 | I8: =E8-G8 -> 1600
A9: AOUT | B9: =IFERROR(__xludf.DUMMYFUNCTION("IMPORTRANGE(""https://docs.google.com/spreadsheets/d/1zA5LDh046PMNVU8ONXHA9gKBkE8m_N5laGAT0t2JyUg/edit?usp=sharing"",""Perf_agents!B16"")"),2.0) -> 2 | C9: =IFERROR(__xludf.DUMMYFUNCTION("IMPORTRANGE(""https://docs.google.com/spreadsheets/d/1zA5LDh046PMNVU8ONXHA9gKBkE8m_N5laGAT0t2JyUg/edit?usp=sharing"",""Perf_agents!B33"")"),2.0) -> 2 | D9: =IFERROR(__xludf.DUMMYFUNCTION("IMPORTRANGE(""https://docs.google.com/spreadsheets/d/1zA5LDh046PMNVU8ONXHA9gKBkE8m_N5laGAT0t2JyUg/edit?usp=sharing"",""Perf_agents!C16"")"),14166.666666666668) -> 14166.667 | E9: =IFERROR(__xludf.DUMMYFUNCTION("IMPORTRANGE(""https://docs.google.com/spreadsheets/d/1zA5LDh046PMNVU8ONXHA9gKBkE8m_N5laGAT0t2JyUg/edit?usp=sharing"",""Perf_agents!C33"")"),19166.666666666668) -> 19166.667 | F9: =IFERROR(__xludf.DUMMYFUNCTION("IMPORTRANGE(""https://docs.google.com/spreadsheets/d/1zA5LDh046PMNVU8ONXHA9gKBkE8m_N5laGAT0t2JyUg/edit?usp=sharing"",""Perf_agents!D9"")"),0.0) -> 0 | G9: =IFERROR(__xludf.DUMMYFUNCTION("IMPORTRANGE(""https://docs.google.com/spreadsheets/d/1zA5LDh046PMNVU8ONXHA9gKBkE8m_N5laGAT0t2JyUg/edit?usp=sharing"",""Perf_agents!D33"")"),11500.0) -> 11500 | H9: =D9-F9 -> 14166.667 | I9: =E9-G9 -> 7666.6667
A10: SEPTEMBRE | B10: =IFERROR(__xludf.DUMMYFUNCTION("IMPORTRANGE(""https://docs.google.com/spreadsheets/d/1zA5LDh046PMNVU8ONXHA9gKBkE8m_N5laGAT0t2JyUg/edit?usp=sharing"",""Perf_agents!B17"")"),0.0) -> 0 | C10: =IFERROR(__xludf.DUMMYFUNCTION("IMPORTRANGE(""https://docs.google.com/spreadsheets/d/1zA5LDh046PMNVU8ONXHA9gKBkE8m_N5laGAT0t2JyUg/edit?usp=sharing"",""Perf_agents!B34"")"),2.0) -> 2 | D10: =IFERROR(__xludf.DUMMYFUNCTION("IMPORTRANGE(""https://docs.google.com/spreadsheets/d/1zA5LDh046PMNVU8ONXHA9gKBkE8m_N5laGAT0t2JyUg/edit?usp=sharing"",""Perf_agents!C17"")"),0.0) -> 0 | E10: =IFERROR(__xludf.DUMMYFUNCTION("IMPORTRANGE(""https://docs.google.com/spreadsheets/d/1zA5LDh046PMNVU8ONXHA9gKBkE8m_N5laGAT0t2JyUg/edit?usp=sharing"",""Perf_agents!C34"")"),16666.666666666668) -> 16666.667 | F10: =IFERROR(__xludf.DUMMYFUNCTION("IMPORTRANGE(""https://docs.google.com/spreadsheets/d/1zA5LDh046PMNVU8ONXHA9gKBkE8m_N5laGAT0t2JyUg/edit?usp=sharing"",""Perf_agents!D9"")"),0.0) -> 0 | G10: =IFERROR(__xludf.DUMMYFUNCTION("IMPORTRANGE(""https://docs.google.com/spreadsheets/d/1zA5LDh046PMNVU8ONXHA9gKBkE8m_N5laGAT0t2JyUg/edit?usp=sharing"",""Perf_agents!D34"")"),10000.0) -> 10000 | H10: =D10-F10 -> 0 | I10: =E10-G10 -> 6666.6667
A11: OCTOBRE | B11: =IFERROR(__xludf.DUMMYFUNCTION("IMPORTRANGE(""https://docs.google.com/spreadsheets/d/1zA5LDh046PMNVU8ONXHA9gKBkE8m_N5laGAT0t2JyUg/edit?usp=sharing"",""Perf_agents!B18"")"),3.0) -> 3 | C11: =IFERROR(__xludf.DUMMYFUNCTION("IMPORTRANGE(""https://docs.google.com/spreadsheets/d/1zA5LDh046PMNVU8ONXHA9gKBkE8m_N5laGAT0t2JyUg/edit?usp=sharing"",""Perf_agents!B35"")"),2.0) -> 2 | D11: =IFERROR(__xludf.DUMMYFUNCTION("IMPORTRANGE(""https://docs.google.com/spreadsheets/d/1zA5LDh046PMNVU8ONXHA9gKBkE8m_N5laGAT0t2JyUg/edit?usp=sharing"",""Perf_agents!C18"")"),18333.333333333336) -> 18333.333 | E11: =IFERROR(__xludf.DUMMYFUNCTION("IMPORTRANGE(""https://docs.google.com/spreadsheets/d/1zA5LDh046PMNVU8ONXHA9gKBkE8m_N5laGAT0t2JyUg/edit?usp=sharing"",""Perf_agents!C35"")"),17500.0) -> 17500 | F11: =IFERROR(__xludf.DUMMYFUNCTION("IMPORTRANGE(""https://docs.google.com/spreadsheets/d/1zA5LDh046PMNVU8ONXHA9gKBkE8m_N5laGAT0t2JyUg/edit?usp=sharing"",""Perf_agents!D9"")"),0.0) -> 0 | G11: =IFERROR(__xludf.DUMMYFUNCTION("IMPORTRANGE(""https://docs.google.com/spreadsheets/d/1zA5LDh046PMNVU8ONXHA9gKBkE8m_N5laGAT0t2JyUg/edit?usp=sharing"",""Perf_agents!D35"")"),10500.0) -> 10500 | H11: =D11-F11 -> 18333.333 | I11: =E11-G11 -> 7000
A12: NOVEMBRE | B12: =IFERROR(__xludf.DUMMYFUNCTION("IMPORTRANGE(""https://docs.google.com/spreadsheets/d/1zA5LDh046PMNVU8ONXHA9gKBkE8m_N5laGAT0t2JyUg/edit?usp=sharing"",""Perf_agents!B19"")"),2.0) -> 2 | C12: =IFERROR(__xludf.DUMMYFUNCTION("IMPORTRANGE(""https://docs.google.com/spreadsheets/d/1zA5LDh046PMNVU8ONXHA9gKBkE8m_N5laGAT0t2JyUg/edit?usp=sharing"",""Perf_agents!B36"")"),0.0) -> 0 | D12: =IFERROR(__xludf.DUMMYFUNCTION("IMPORTRANGE(""https://docs.google.com/spreadsheets/d/1zA5LDh046PMNVU8ONXHA9gKBkE8m_N5laGAT0t2JyUg/edit?usp=sharing"",""Perf_agents!C19"")"),15000.0) -> 15000 | E12: =IFERROR(__xludf.DUMMYFUNCTION("IMPORTRANGE(""https://docs.google.com/spreadsheets/d/1zA5LDh046PMNVU8ONXHA9gKBkE8m_N5laGAT0t2JyUg/edit?usp=sharing"",""Perf_agents!C36"")"),0.0) -> 0 | F12: =IFERROR(__xludf.DUMMYFUNCTION("IMPORTRANGE(""https://docs.google.com/spreadsheets/d/1zA5LDh046PMNVU8ONXHA9gKBkE8m_N5laGAT0t2JyUg/edit?usp=sharing"",""Perf_agents!D9"")"),0.0) -> 0 | G12: =IFERROR(__xludf.DUMMYFUNCTION("IMPORTRANGE(""https://docs.google.com/spreadsheets/d/1zA5LDh046PMNVU8ONXHA9gKBkE8m_N5laGAT0t2JyUg/edit?usp=sharing"",""Perf_agents!D36"")"),0.0) -> 0 | H12: =D12-F12 -> 15000 | I12: =E12-G12 -> 0
A13: DECEMBRE | B13: =IFERROR(__xludf.DUMMYFUNCTION("IMPORTRANGE(""https://docs.google.com/spreadsheets/d/1zA5LDh046PMNVU8ONXHA9gKBkE8m_N5laGAT0t2JyUg/edit?usp=sharing"",""Perf_agents!B20"")"),3.0) -> 3 | C13: =IFERROR(__xludf.DUMMYFUNCTION("IMPORTRANGE(""https://docs.google.com/spreadsheets/d/1zA5LDh046PMNVU8ONXHA9gKBkE8m_N5laGAT0t2JyUg/edit?usp=sharing"",""Perf_agents!B37"")"),1.0) -> 1 | D13: =IFERROR(__xludf.DUMMYFUNCTION("IMPORTRANGE(""https://docs.google.com/spreadsheets/d/1zA5LDh046PMNVU8ONXHA9gKBkE8m_N5laGAT0t2JyUg/edit?usp=sharing"",""Perf_agents!C20"")"),24166.666666666668) -> 24166.667 | E13: =IFERROR(__xludf.DUMMYFUNCTION("IMPORTRANGE(""https://docs.google.com/spreadsheets/d/1zA5LDh046PMNVU8ONXHA9gKBkE8m_N5laGAT0t2JyUg/edit?usp=sharing"",""Perf_agents!C37"")"),5833.333333333334) -> 5833.3333 | F13: =IFERROR(__xludf.DUMMYFUNCTION("IMPORTRANGE(""https://docs.google.com/spreadsheets/d/1zA5LDh046PMNVU8ONXHA9gKBkE8m_N5laGAT0t2JyUg/edit?usp=sharing"",""Perf_agents!D9"")"),0.0) -> 0 | G13: =IFERROR(__xludf.DUMMYFUNCTION("IMPORTRANGE(""https://docs.google.com/spreadsheets/d/1zA5LDh046PMNVU8ONXHA9gKBkE8m_N5laGAT0t2JyUg/edit?usp=sharing"",""Perf_agents!D37"")"),3500.0000000000005) -> 3500 | H13: =D13-F13 -> 24166.667 | I13: =E13-G13 -> 2333.3333

Sheet Graph15_evolution_ventes_alex
A1: ANNEE | B1: VENTES_BILAN | C1: VENTES_REELLES
A2: 2021 | B2: 13 | C2: 14
A3: 2022 | B3: 20 | C3: 26
A4: 2023 | B4: 26 | C4: 32

Sheet Graph16_evolution_ventes_lisa
A1: ANNEE | B1: VENTES_BILAN | C1: VENTES_REELLES
A2: 2021 | B2: 20 | C2: 20
A3: 2022 | B3: 13 | C3: 19
A4: 2023 | B4: 19 | C4: 14

Sheet Graph17_sources_ventes_alex
A1: CRITERES | B1: COL_1
A2: VENTES_BILAN_RESEAU_PERSO_ALEX | B2: 19
A3: VENTES_BILAN_DIGITAL_ALEX | B3: 7
A4: VENTES_REPORTEES_RESEAU_PERSO_ALEX | B4: 3
A5: VENTES_REPORTEES_DIGITAL_ALEX | B5: 3

Sheet Graph18_sources_ventes_lisa
A1: CRITERES | B1: COL_1
A2: VENTES_BILAN_RESEAU_PERSO_LISA | B2: 10
A3: VENTES_BILAN_DIGITAL_LISA | B3: 7
A4: VENTES_BILAN_PROXIMITE_LISA | B4: 1
A5: VENTES_BILAN_DELEGATION_MANDAT_LISA | B5: 1
A6: VENTES_REPORTEES_RESEAU_PERSO_LISA | B6: 1
A7: VENTES_REPORTEES_DIGITAL_LISA | B7: 0

Sheet Graph19_contribution_CA_all
A1: CRITERES | B1: COL_1
A2: CONTRIBUTION_CA_NET_BILAN_ALEX | B2: =IFERROR(__xludf.DUMMYFUNCTION("IMPORTRANGE(""https://docs.google.com/spreadsheets/d/1zA5LDh046PMNVU8ONXHA9gKBkE8m_N5laGAT0t2JyUg/edit?usp=sharing"",""Ventes RESIDE 2023!J75"")"),"#REF!") -> #REF!
A3: CONTRIBUTION_CA_NET_BILAN_LISA | B3: =IFERROR(__xludf.DUMMYFUNCTION("IMPORTRANGE(""https://docs.google.com/spreadsheets/d/1zA5LDh046PMNVU8ONXHA9gKBkE8m_N5laGAT0t2JyUg/edit?usp=sharing"",""Ventes RESIDE 2023!J77"")"),"#REF!") -> #REF!
A4: CONTRIBUTION_CA_NET_BILAN_DIGITAL
A5: CONTRIBUTION_CA_NET_REPORTEES_ALEX | B5: =IFERROR(__xludf.DUMMYFUNCTION("IMPORTRANGE(""https://docs.google.com/spreadsheets/d/1zA5LDh046PMNVU8ONXHA9gKBkE8m_N5laGAT0t2JyUg/edit?usp=sharing"",""Ventes RESIDE 2023!J76"")"),"#REF!") -> #REF!
A6: CONTRIBUTION_CA_NET_REPORTEES_LISA | B6: =IFERROR(__xludf.DUMMYFUNCTION("IMPORTRANGE(""https://docs.google.com/spreadsheets/d/1zA5LDh046PMNVU8ONXHA9gKBkE8m_N5laGAT0t2JyUg/edit?usp=sharing"",""Ventes RESIDE 2023!J78"")"),"#REF!") -> #REF!
A7: CONTRIBUTION_CA_NET_REPORTEES_DIGITAL

Sheet Data_chiffre_affaires
A1: CRITERES | B1: COL_1
A2: CA_AJOUTE_2022 | B2: =IFERROR(__xludf.DUMMYFUNCTION("IMPORTRANGE(""https://docs.google.com/spreadsheets/d/1zA5LDh046PMNVU8ONXHA9gKBkE8m_N5laGAT0t2JyUg/edit?usp=sharing"",""Perf_globales!G3"")"),71666.66666666667) -> 71666.667
A3: CA_REEL_2023 | B3: =IFERROR(__xludf.DUMMYFUNCTION("IMPORTRANGE(""https://docs.google.com/spreadsheets/d/1zA5LDh046PMNVU8ONXHA9gKBkE8m_N5laGAT0t2JyUg/edit?usp=sharing"",""Perf_globales!J3"")"),290133.3299999999) -> 290133.33
A4: CA_AUTRES_SERVICES | B4: =IFERROR(__xludf.DUMMYFUNCTION("IMPORTRANGE(""https://docs.google.com/spreadsheets/d/1zA5LDh046PMNVU8ONXHA9gKBkE8m_N5laGAT0t2JyUg/edit?usp=sharing"",""Perf_globales!D13"")"),10202.82) -> 10202.82
A5: CA_REPORTE_2024 | B5: =IFERROR(__xludf.DUMMYFUNCTION("IMPORTRANGE(""https://docs.google.com/spreadsheets/d/1zA5LDh046PMNVU8ONXHA9gKBkE8m_N5laGAT0t2JyUg/edit?usp=sharing"",""Perf_globales!M3"")"),41458.333333333336) -> 41458.333
A6: CA_AMELIORE_2023 | B6: =IFERROR(__xludf.DUMMYFUNCTION("IMPORTRANGE(""https://docs.google.com/spreadsheets/d/1zA5LDh046PMNVU8ONXHA9gKBkE8m_N5laGAT0t2JyUg/edit?usp=sharing"",""Perf_globales!B3"")"),372002.8166666666) -> 372002.82
A7: CA_TRAVAILLE | B7: =B3+B4+B5 -> 341794.48
A8: CA_VENTES_BILAN | B8: =B2+B3 -> 361800
A9: TAUX_EVOLUTION_CA_N-1 | B9: =((372000-277368)/277368)*100 -> 34.117851
A10: CA_ENCAISSE | B10: =IFERROR(__xludf.DUMMYFUNCTION("IMPORTRANGE(""https://docs.google.com/spreadsheets/d/1zA5LDh046PMNVU8ONXHA9gKBkE8m_N5laGAT0t2JyUg/edit?usp=sharing"",""Perf_mois!E15"")"),273208.33) -> 273208.33
A14: %_CA_ENCAISSE | B14: =IFERROR(__xludf.DUMMYFUNCTION("IMPORTRANGE(""https://docs.google.com/spreadsheets/d/1zA5LDh046PMNVU8ONXHA9gKBkE8m_N5laGAT0t2JyUg/edit?usp=sharing"",""Perf_mois!E15"")/IMPORTRANGE(""https://docs.google.com/spreadsheets/d/1zA5LDh046PMNVU8ONXHA9gKBkE8m_N5laGAT0t2JyUg/edit?usp=sharing"","""&"Perf_mois!C15"")*100"),75.51363530047573) -> 75.513635
A15: %_CA_COMMISSIONS | B15: =IFERROR(__xludf.DUMMYFUNCTION("IMPORTRANGE(""https://docs.google.com/spreadsheets/d/1zA5LDh046PMNVU8ONXHA9gKBkE8m_N5laGAT0t2JyUg/edit?usp=sharing"",""Perf_mois!D15"")/IMPORTRANGE(""https://docs.google.com/spreadsheets/d/1zA5LDh046PMNVU8ONXHA9gKBkE8m_N5laGAT0t2JyUg/edit?usp=sharing"","""&"Perf_mois!C15"")*100"),24.48636469952427) -> 24.486365
A16: %_CA_RESEAU_PERSO | B16: =IFERROR(__xludf.DUMMYFUNCTION("IMPORTRANGE(""https://docs.google.com/spreadsheets/d/1zA5LDh046PMNVU8ONXHA9gKBkE8m_N5laGAT0t2JyUg/edit?usp=sharing"",""Sources_ventes!D2"")"),56.77630326862265) -> 56.776303
A17: %_CA_NOTORIETE | B17: =IFERROR(__xludf.DUMMYFUNCTION("IMPORTRANGE(""https://docs.google.com/spreadsheets/d/1zA5LDh046PMNVU8ONXHA9gKBkE8m_N5laGAT0t2JyUg/edit?usp=sharing"",""Sources_ventes!D3"")"),11.286161887655812) -> 11.286162
A18: %_CA_CLIENTS_ACHETEUR_VENDEUR | B18: =IFERROR(__xludf.DUMMYFUNCTION("IMPORTRANGE(""https://docs.google.com/spreadsheets/d/1zA5LDh046PMNVU8ONXHA9gKBkE8m_N5laGAT0t2JyUg/edit?usp=sharing"",""Sources_ventes!D4"")"),6.44923536437475) -> 6.4492354
A19: %_CA_DIGITAL | B19: =IFERROR(__xludf.DUMMYFUNCTION("IMPORTRANGE(""https://docs.google.com/spreadsheets/d/1zA5LDh046PMNVU8ONXHA9gKBkE8m_N5laGAT0t2JyUg/edit?usp=sharing"",""Sources_ventes!D5"")"),25.488299479346782) -> 25.488299
A23: CA_ESTIME_2024_HT | B23: =(Data_ventes!C19*Data_commissions!B3)+((Data_ventes!D19*Data_commissions!B3)*0.4) -> 243821.74
A24: CA_MIN_RENTABILITE_2024 | B24: =Data_depenses!B31/1.2 -> 217166.67
A25: CA_ATTENDU_2024 | B25: =B23-B5 -> 202363.4
A27: RESULTAT POTENTIEL_2024 | B27: =IFERROR(__xludf.DUMMYFUNCTION("IMPORTRANGE(""https://docs.google.com/spreadsheets/d/19FaQ-n49KvG_bpd6Rh0MfgcMD6HVSCdsRH5fCIUeJXQ/edit?usp=sharing"",""SITUATION_2024!I135"") "),"")
A28: IS POTENTIEL_2024 | B28: =IFERROR(__xludf.DUMMYFUNCTION("IMPORTRANGE(""https://docs.google.com/spreadsheets/d/19FaQ-n49KvG_bpd6Rh0MfgcMD6HVSCdsRH5fCIUeJXQ/edit?usp=sharing"",""SITUATION_2024!I138"") "),"")
A29: RESULTAT POTENTIEL_2023 | B29: 70995
A30: IS POTENTIEL_2023 | B30: 13038

Sheet Data_ventes
A1: CRITERES | B1: COL_1 | C1: COL_2 | D1: COL_3
A2: VENTES_2023 | B2: =IFERROR(__xludf.DUMMYFUNCTION("IMPORTRANGE(""https://docs.google.com/spreadsheets/d/1zA5LDh046PMNVU8ONXHA9gKBkE8m_N5laGAT0t2JyUg/edit?usp=sharing"",""Perf_globales!C3"")"),46.0) -> 46
A3: VENTES_2022 | B3: 37
A4: VENTES_AJOUTE_2022 | B4: =IFERROR(__xludf.DUMMYFUNCTION("IMPORTRANGE(""https://docs.google.com/spreadsheets/d/1zA5LDh046PMNVU8ONXHA9gKBkE8m_N5laGAT0t2JyUg/edit?usp=sharing"",""Perf_globales!F3"")"),10.0) -> 10
A5: VENTES_REELLES_2023 | B5: =IFERROR(__xludf.DUMMYFUNCTION("IMPORTRANGE(""https://docs.google.com/spreadsheets/d/1zA5LDh046PMNVU8ONXHA9gKBkE8m_N5laGAT0t2JyUg/edit?usp=sharing"",""Perf_globales!I3"")"),36.0) -> 36
A6: VENTES_REPORTEES_2024 | B6: =IFERROR(__xludf.DUMMYFUNCTION("IMPORTRANGE(""https://docs.google.com/spreadsheets/d/1zA5LDh046PMNVU8ONXHA9gKBkE8m_N5laGAT0t2JyUg/edit?usp=sharing"",""Perf_globales!L3"")"),7.0) -> 7
A7: VENTES_AMELIOREES_2023 | B7: =IFERROR(__xludf.DUMMYFUNCTION("IMPORTRANGE(""https://docs.google.com/spreadsheets/d/1zA5LDh046PMNVU8ONXHA9gKBkE8m_N5laGAT0t2JyUg/edit?usp=sharing"",""Perf_globales!C3"")"),46.0) -> 46
A8: VENTES_TRAVAILLE | B8: =IFERROR(__xludf.DUMMYFUNCTION("IMPORTRANGE(""https://docs.google.com/spreadsheets/d/1zA5LDh046PMNVU8ONXHA9gKBkE8m_N5laGAT0t2JyUg/edit?usp=sharing"",""Perf_globales!O3"")"),43.0) -> 43
A9: TAUX_EVOLUTION_VENTES_N-1 | B9: =((46-37)/37)*100 -> 24.324324
A10: MANDATS_TOTAL | B10: 72
A11: TAUX_MANDATS_VENDUS | B11: =B8/B10*100 -> 59.722222
A12: MANDATS_ANNULES | B12: 11
A13: MANDATS_VENDU_CONCURRENT | B13: 2
A14: VENDU_RESIDE | B14: 44
A15: MANDATS_STOCK | B15: =B10-B14-B13-B12 -> 15
C18: Ventes Alex | D18: Ventes Lisa
A19: VENTES_ESTIMEES_2024 | B19: 40 | C19: 25 | D19: 15
A20: VENTES_MIN_RENTABILITE | B20: =Data_depenses!B31/Data_commissions!B3 -> 33.133223
A21: VENTES_ATTENDUES_2024 | B21: =B19-B6 -> 33

Sheet Data_commissions
A1: CRITERES | B1: COL_1
A2: COMMISSIONS_BILAN | B2: =IFERROR(__xludf.DUMMYFUNCTION("IMPORTRANGE(""https://docs.google.com/spreadsheets/d/1zA5LDh046PMNVU8ONXHA9gKBkE8m_N5laGAT0t2JyUg/edit?usp=sharing"",""Perf_mois!D15"")"),88591.66666666666) -> 88591.667
A3: COMMISSION_MOYENNE_HT | B3: =IFERROR(__xludf.DUMMYFUNCTION("IMPORTRANGE(""https://docs.google.com/spreadsheets/d/1zA5LDh046PMNVU8ONXHA9gKBkE8m_N5laGAT0t2JyUg/edit?usp=sharing"",""Perf_globales!A16"")"),7865.217318840578) -> 7865.2173

Sheet Data_depenses
A1: CRITERES | B1: COL_1 | C1: COL_2 | D1: COL_3 | E1: COL_4 | F1: COL_5
A2: TRESORERIE_JAN_N | B2: =IFERROR(__xludf.DUMMYFUNCTION("IMPORTRANGE(""https://docs.google.com/spreadsheets/d/1zA5LDh046PMNVU8ONXHA9gKBkE8m_N5laGAT0t2JyUg/edit?usp=sharing"",""Depenses_tresorerie!B4"")"),60325.0) -> 60325
A3: TRESORERIE_DEC_N | B3: =IFERROR(__xludf.DUMMYFUNCTION("IMPORTRANGE(""https://docs.google.com/spreadsheets/d/1zA5LDh046PMNVU8ONXHA9gKBkE8m_N5laGAT0t2JyUg/edit?usp=sharing"",""Depenses_tresorerie!N4"")"),"")
A4: DELTA_TRESORERIE | B4: =B5-B8 -> -10812.764
A5: ENCAISSEMENTS_TOTAL_ANNEE_TTC | B5: =IFERROR(__xludf.DUMMYFUNCTION("IMPORTRANGE(""https://docs.google.com/spreadsheets/d/1zA5LDh046PMNVU8ONXHA9gKBkE8m_N5laGAT0t2JyUg/edit?usp=sharing"",""Depenses_tresorerie!N7"")+IMPORTRANGE(""https://docs.google.com/spreadsheets/d/1zA5LDh046PMNVU8ONXHA9gKBkE8m_N5laGAT0t2JyUg/edit?usp=sha"&"ring"",""Depenses_tresorerie!N9"")"),506911.996) -> 506912 | C5: =B8/B5*100 -> 102.13307
A6: ENCAISSEMENTS_VENTES_TTC | B6: =IFERROR(__xludf.DUMMYFUNCTION("IMPORTRANGE(""https://docs.google.com/spreadsheets/d/1zA5LDh046PMNVU8ONXHA9gKBkE8m_N5laGAT0t2JyUg/edit?usp=sharing"",""Depenses_tresorerie!N7"")"),434159.996) -> 434160 | D6: =B6/B5 -> 0.85648002
A7: AUTRES_ENCAISSEMENTS_TTC | B7: =IFERROR(__xludf.DUMMYFUNCTION("IMPORTRANGE(""https://docs.google.com/spreadsheets/d/1zA5LDh046PMNVU8ONXHA9gKBkE8m_N5laGAT0t2JyUg/edit?usp=sharing"",""Depenses_tresorerie!N9"")"),72752.0) -> 72752 | D7: =B7/B5 -> 0.14351998
A8: DECAISSEMENTS_TOTAL_ANNEE_TTC | B8: =IFERROR(__xludf.DUMMYFUNCTION("IMPORTRANGE(""https://docs.google.com/spreadsheets/d/1zA5LDh046PMNVU8ONXHA9gKBkE8m_N5laGAT0t2JyUg/edit?usp=sharing"",""Depenses_tresorerie!N23"")"),517724.76) -> 517724.76 | C8: =B10+B11+B12 -> 315108.57 | F8: =B8/1.2 -> 431437.3
A9: TOTAL_COMMISSIONS_VERSEES_HT | B9: =IFERROR(__xludf.DUMMYFUNCTION("IMPORTRANGE(""https://docs.google.com/spreadsheets/d/1zA5LDh046PMNVU8ONXHA9gKBkE8m_N5laGAT0t2JyUg/edit?usp=sharing"",""Depenses_tresorerie!N11"")"),87399.99666666667) -> 87399.997 | D9: =B9/B8 -> 0.16881556 | E9: =B9/B5 -> 0.17241651
A10: TOTAL_DEPENSES_COURANTES_TTC | B10: =IFERROR(__xludf.DUMMYFUNCTION("IMPORTRANGE(""https://docs.google.com/spreadsheets/d/1zA5LDh046PMNVU8ONXHA9gKBkE8m_N5laGAT0t2JyUg/edit?usp=sharing"",""Depenses_tresorerie!N14"")"),200005.63999999998) -> 200005.64 | C10: =B10/12 -> 16667.137 | D10: =B10/B8 -> 0.38631654 | E10: =B10/B5 -> 0.39455693
A11: TOTAL_DEPENSES_EXCEPTIONNELLES_TTC | B11: =IFERROR(__xludf.DUMMYFUNCTION("IMPORTRANGE(""https://docs.google.com/spreadsheets/d/1zA5LDh046PMNVU8ONXHA9gKBkE8m_N5laGAT0t2JyUg/edit?usp=sharing"",""Depenses_tresorerie!N16"")"),102617.75) -> 102617.75 | D11: =B11/B8 -> 0.19820908 | E11: =B11/B5 -> 0.20243701 | F11: =B11/1.2 -> 85514.792
A12: TOTAL_NOTES_DE_FRAIS_TTC | B12: =IFERROR(__xludf.DUMMYFUNCTION("IMPORTRANGE(""https://docs.google.com/spreadsheets/d/1zA5LDh046PMNVU8ONXHA9gKBkE8m_N5laGAT0t2JyUg/edit?usp=sharing"",""Depenses_tresorerie!N18"")"),12485.18) -> 12485.18 | D12: =B12/B8 -> 0.024115478 | E12: =B12/B5 -> 0.024629877
A13: TOTAL_TVA | B13: =IFERROR(__xludf.DUMMYFUNCTION("IMPORTRANGE(""https://docs.google.com/spreadsheets/d/1zA5LDh046PMNVU8ONXHA9gKBkE8m_N5laGAT0t2JyUg/edit?usp=sharing"",""Depenses_tresorerie!N19"")"),63256.0) -> 63256 | D13: =B13/B8 -> 0.12218075 | E13: =B13/B5 -> 0.12478695
A14: TOTAL_SALAIRES | B14: =IFERROR(__xludf.DUMMYFUNCTION("IMPORTRANGE(""https://docs.google.com/spreadsheets/d/1zA5LDh046PMNVU8ONXHA9gKBkE8m_N5laGAT0t2JyUg/edit?usp=sharing"",""Depenses_tresorerie!N20"")"),15901.689999999999) -> 15901.69 | D14: =B14/B8 -> 0.030714563 | E14: =B14/B5 -> 0.031369725
A15: TOTAL_DEPENSE_EN_+ | B15: =IFERROR(__xludf.DUMMYFUNCTION("IMPORTRANGE(""https://docs.google.com/spreadsheets/d/1zA5LDh046PMNVU8ONXHA9gKBkE8m_N5laGAT0t2JyUg/edit?usp=sharing"",""Depenses_tresorerie!N21"")"),105108.56999999999) -> 105108.57
A16: DEPENSES_COURANTES_ANNUELLES_ESTIMEES | B16: =16000*12 -> 192000
A17: DEPENSES_COURANTES_MENSUELLES_ESTIMEES | B17: =B16/12 -> 16000
A18: DIFF_DEPENSES_COURANTES | B18: =B10-B16 -> 8005.64
A19: DEPENSES_EXCEPTIONNELLES_ANNUELLES_ESTIMEES | B19: =1000*12 -> 12000
A20: DEPENSES_EXCEPTIONNELLES_MENSUELLES_ESTIMEES | B20: 1000
A21: DIFF_DEPENSES_EXCEPTIONNELLES | B21: =B11-B19 -> 90617.75
A22: DEPENSES_NOTES_FRAIS_ANNUELLES_ESTIMEES | B22: =500*12 -> 6000
A23: DEPENSES_NOTES_FRAIS_MENSUELLES_ESTIMEES | B23: =B22/12 -> 500
A24: DIFF_DEPENSES_NOTES_FRAIS | B24: =B12-B22 -> 6485.18
A28: TOTAL_DEPENSES_COURANTES_2024 | B28: =17500*12 -> 210000
A29: TOTAL_DEPENSES_EXCEPTIONNELLES_2024 | B29: =(370000*0.05)+17400+7500 -> 43400 | C29: =(370000*0.05) -> 18500 | D29: =C29/12 -> 1541.6667
A30: TOTAL_NOTES_DE_FRAIS_2024 | B30: =600*12 -> 7200
A31: TOTAL_DEPENSES_2024_TTC | B31: =SUM(B28:B30) -> 260600 | C31: =B31/1.2 -> 217166.67
A32: PART_DEPENSES_CA_PREV | B32: =C31/Data_chiffre_affaires!B23*100 -> 89.067804
A33: PART_DEPENSES_CA_2023 | B33: =((B10+B11+B12)/1.2)/Data_chiffre_affaires!B6*100 -> 70.588303
A34: TOTAL_DEPENSES_COUR_EXCEP_FRAIS_SALAIRE_HT | B34: 319431 | C34: =B34/Data_chiffre_affaires!B6*100 -> 85.867898 | D34: =(B34+B13)/(434160+(Data_chiffre_affaires!B4*1.2))*100 -> 85.726725
A35: TOTAL_ENCAISSEMENTS_HT | B35: =IFERROR(__xludf.DUMMYFUNCTION("IMPORTRANGE(""https://docs.google.com/spreadsheets/d/1zA5LDh046PMNVU8ONXHA9gKBkE8m_N5laGAT0t2JyUg/edit?usp=sharing"",""Depenses_tresorerie!N8"")+IMPORTRANGE(""https://docs.google.com/spreadsheets/d/1zA5LDh046PMNVU8ONXHA9gKBkE8m_N5laGAT0t2JyUg/edit?usp=sha"&"ring"",""Depenses_tresorerie!O9"")"),422426.6633333334) -> 422426.66

Sheet Data_investissements
A1: CRITERES | B1: COL_1 | C1: COL_2 | D1: COL_3 | E1: COL_4
A2: DOTATION_AMORTISSEMENTS_2023_ANCIEN_INVEST | B2: =IFERROR(__xludf.DUMMYFUNCTION("IMPORTRANGE(""https://docs.google.com/spreadsheets/d/1zA5LDh046PMNVU8ONXHA9gKBkE8m_N5laGAT0t2JyUg/edit?usp=sharing"",""Investissements_2023!F15"")"),424.51) -> 424.51
A3: DOTATION_AMORTISSEMENTS_2023_INVEST_ANNEE | B3: =IFERROR(__xludf.DUMMYFUNCTION("IMPORTRANGE(""https://docs.google.com/spreadsheets/d/1zA5LDh046PMNVU8ONXHA9gKBkE8m_N5laGAT0t2JyUg/edit?usp=sharing"",""Investissements_2023!F13"")"),115.14) -> 115.14
A4: DOTATION_TOTALE_AMORTISSEMENTS_2023 | B4: =IFERROR(__xludf.DUMMYFUNCTION("IMPORTRANGE(""https://docs.google.com/spreadsheets/d/1zA5LDh046PMNVU8ONXHA9gKBkE8m_N5laGAT0t2JyUg/edit?usp=sharing"",""Investissements_2023!F16"")"),1897.3) -> 1897.3
A5: DOTATION_TOTALE_AMORTISSEMENTS_2024 | B5: =IFERROR(__xludf.DUMMYFUNCTION("IMPORTRANGE(""https://docs.google.com/spreadsheets/d/1zA5LDh046PMNVU8ONXHA9gKBkE8m_N5laGAT0t2JyUg/edit?usp=sharing"",""Investissements_2023!J16"")"),"travaux bâtiment - Ne concerne pas RESIDE") -> travaux bâtiment - Ne concerne pas RESIDE
